Workbook
Name 가격기준: #REF!
Name 가격테이블: HLOOKUP!$A$2:$I$4
Name 계절변수: VLOOKUP!$I$5
Name 기준테이블: VLOOKUP!$A$6:$E$10
Name 기준테이블1: VLOOKUP!$A$5:$E$13
Name 메뉴가격: 회식비!$I$14:$J$22
Name 미화환율: #REF!
Name 카페가격테이블: HLOOKUP!$K$8:$P$10
Name 팀분류: 회식비!$I$3:$J$11
Name 환율표: #REF!

Sheet VISICALC
A29: VISICALC (1979년)
A66: LOTUS 1-2-3 (1983년)
A104: EXCEL (1985년)

Sheet 기본함수
A1: 기본함수
A2: 날짜/시간 | B2: DATE | P2: 파일이름 알아내기 | Q2: {=CELL("filename")} -> C:\Users\User\AppData\Local\Temp\BNZ.68d1e2501857e328\KIKcd_B.20210101.xlsx
B3: TODAY | C3: NOW | J3: .. | P3: 현 시트이름 알아내기 | Q3: {=MID( CELL("filename"), FIND("]", CELL("filename"))+1,50)} -> #VALUE!
B4: MID | C4: LEFT | D4: RIGHT
B5: WEEKDAY
B6: YEAR | D6: REPLACE
P8: 행열 숨기기
A9: 수학 | B9: SUM | C9: SUMIF | P9: 상동내용입력 | Q9: alt+아래화살표
B10: ROUND | C10: ROUNDUP | D10: ROUNDDOWN | J10: 주요기능 | Q10: tab키로 입력,마지막 enter
B11: SUMPRODUCT | J11: 데이타입력 | P11: 날짜 | Q11: 하이픈,스래쉬
B12: MOD | C12: 1 | D12: 2 | J12: 함수 | P12: 현재날짜 | Q12: 콘트롤+;
J13: 조건부서식 | P13: 현재시간 | Q13: 콘트롤+:
J14: 데이타유효성검사 | P14: 자동채우기 | Q14: 옵션으로 설정
A15: 통계 | B15: AVERAGE | J15: 고급필터 | P15: 사용자지정 | Q15: 파일-옵션-고급-일반-
B16: RANK | J16: 목표값찾기 | P16: 빠른채우기
B17: MIN | C17: MAX | J17: 피벗 | P17: 시트컨트롤,보호
B18: COUNT | C18: COUNTA | D18: COUNTIF | J18: 정렬및 부분합 | P18: 빠른실행도구모음(alt+1,2,3,4)
B19: LARGE | J19: 챠트 | P19: ALTER키 활용
P20: 그림으로 붙여넣기
A22: 논리 | B22: IF | C22: AND | D22: OR
B23: IFERROR | P23: Win+Shift+S : 캡쳐
P24: chrome://chrome-urls
A25: 찾기/참조 | B25: INDEX | C25: MATCH | D25: CHOOSE
B26: VLOOKUP | C26: HLOOKUP
B27: CHOOSE | C27: OFFSET | D27: TRANSPOSE
B28: REPLACE
A30: DATABASE | B30: DSUM | C30: DAVERAGE
B31: DCOUNT
B32: DCOUNTA
A34: 배열함수

Sheet FILENAME
A1: 1 | B1: 파일이름 알아내기 | C1: {=CELL("filename")} -> C:\Users\User\AppData\Local\Temp\BNZ.68d1e2501857e328\KIKcd_B.20210101.xlsx
A2: 2 | B2: 현 시트이름 알아내기 | C2: {=MID( CELL("filename"), FIND("]", CELL("filename"))+1,50)} -> #VALUE!
A3: 3
A4: 4
A5: 5
B8: A열 이름으로 시트명 만들기 | C8: 피봇에서 필터로 보고서 만들기로 A열 이름으로 시트를 5개 만들고 시트이름을 시트에서 활용 보고서 발행
A9: 참고 | B9: https://www.youtube.com/watch?v=bpmDJicKfMA
C14: 1 | D14: (모두)
B16: 모든 엑셀함수를 VBA에서 사용가능
B17: WorksheetFunction.Isodd()

Sheet 날짜
D3: 44667 | E3: =NOW() -> 45923.373
E4: =TODAY() -> 45923
D5: 40471
C6: 2 | D6: =$D$5+(C6-1) -> 40472 | AA6: =REPLACE(H6,5,4,"XXXX") -> XXXX
C7: 5 | D7: =$D$5+(C7-1) -> 40475 | AA7: =REPLACE(H7,5,4,"XXXX") -> XXXX
C8: 100 | D8: =$D$5+(C8-1) -> 40570 | AA8: =REPLACE(H8,5,4,"XXXX") -> XXXX
C9: 200 | D9: =IF($D$5="","",$D$5+(C9-1)) -> 40670 | AA9: =REPLACE(H9,5,4,"XXXX") -> XXXX
C10: 500 | D10: =IF($D$5="","",$D$5+(C10-1)) -> 40970 | AA10: =REPLACE(H10,5,4,"XXXX") -> XXXX
C11: 1000 | D11: =IF($D$5="","",$D$5+(C11-1)) -> 41470 | AA11: =REPLACE(H11,5,4,"XXXX") -> XXXX
C12: 5000 | D12: =IF($D$5="","",$D$5+(C12-1)) -> 45470 | AA12: =REPLACE(H12,5,4,"XXXX") -> XXXX
AA13: =REPLACE(H13,5,4,"XXXX") -> XXXX
AA14: =REPLACE(H14,5,4,"XXXX") -> XXXX
AA15: =REPLACE(H15,5,4,"XXXX") -> XXXX
AA16: =REPLACE(H16,5,4,"XXXX") -> XXXX
AA17: =REPLACE(H17,5,4,"XXXX") -> XXXX
H309: 010-1234-5735
H310: 010-1234-5736
H311: 010-1234-5737
H312: 010-1234-5738
H313: 010-1234-5739
H314: 010-1234-5740
H315: 010-1234-5741
H316: 010-1234-5742
H317: 010-1234-5743
H318: 010-1234-5744
H319: 010-1234-5745
H320: 010-1234-5746
... H1524: 010-1234-6950

Sheet 성적
B2: 3학년1반 | C2: 5월말고사
C3: 이름 | D3: 국어 | E3: 수학 | F3: 과학 | G3: 영어 | H3: 국사 | I3: 총점 | J3: 평균 | K3: 석차 | R3: countif
B4: 12 | C4: 김철수 | D4: 96 | E4: 92 | F4: 87 | G4: 94 | H4: 90 | R4: 인원수
B5: 3 | C5: 안가람 | D5: 92 | E5: 98 | F5: 89 | G5: 89 | H5: 78 | Q5: 합격
B6: 7 | C6: 한지선 | D6: 90 | E6: 89 | F6: 97 | G6: 94 | H6: 90 | Q6: 불합격
B7: 1 | C7: 조영종 | D7: 89 | E7: 65 | F7: 65 | G7: 76 | H7: 87 | R7: sumif
B8: 13 | C8: 박준산 | D8: 89 | E8: 76 | F8: 65 | G8: 54 | H8: 65 | R8: 총점합계
B9: 10 | C9: 서은미 | D9: 89 | E9: 45 | F9: 89 | G9: 65 | H9: 65 | Q9: 평균이상
B10: 16 | C10: 손준승 | D10: 89 | E10: 54 | F10: 54 | G10: 54 | H10: 43 | Q10: 평균이하
B11: 18 | C11: 이재명 | D11: 89 | E11: 96 | F11: 92 | G11: 89 | H11: 93
B12: 19 | C12: 유미 | D12: 89 | E12: 67 | F12: 67 | G12: 91 | H12: 94
B13: 9 | C13: 조현진 | D13: 89 | E13: 65 | F13: 89 | G13: 54 | H13: 97
B14: 8 | C14: 이정호 | D14: 88 | E14: 56 | F14: 89 | G14: 89 | H14: 95
B15: 11 | C15: 최형담 | D15: 87 | E15: 54 | F15: 34 | G15: 45 | H15: 89
B16: 2 | C16: 전정수 | D16: 78 | E16: 78 | F16: 76 | G16: 87 | H16: 56
B17: 4 | C17: 양홍숙 | D17: 76 | E17: 78 | F17: 89 | G17: 66 | H17: 89
B18: 14 | C18: 백해룡 | D18: 76 | E18: 76 | F18: 55 | G18: 74 | H18: 76
B19: 6 | C19: 정사랑 | D19: 65 | E19: 54 | F19: 89 | G19: 65 | H19: 65
B20: 5 | C20: 이영미 | D20: 56 | E20: 89 | F20: 89 | G20: 90 | H20: 89
B21: 15 | C21: 이미숙 | D21: 45 | E21: 56 | F21: 87 | G21: 74 | H21: 97
B22: 17 | C22: 윤석열 | D22: 34 | E22: 54 | F22: 54 | G22: 32 | H22: 43

Sheet IF
B3: 700101-1658820 | C3: 정형준 | D3: =MID(C3,2,1) -> 형 | E3: =REPLACE(C3,2,1,"X") -> 정X준 | I3: 1 | J3: =IF(I3=1,"XXX","YYY") -> XXX | M3: 학력
B4: 700101-2658821 | C4: 이춘식 | D4: =MID(C4,2,1) -> 춘 | E4: =REPLACE(C4,2,1,"X") -> 이X식 | I4: 2 | J4: =IF(I4=1,"XXX","YYY") -> YYY | M4: 1 | N4: =IF(M4=1,"대졸",IF(M4=2,"고졸","중졸")) -> 대졸
B5: 700101-4658822 | C5: 김수민 | D5: =MID(C5,2,1) -> 수 | E5: =REPLACE(C5,2,1,"X") -> 김X민 | I5: 1 | J5: =IF(I5=1,"XXX","YYY") -> XXX | M5: 3 | N5: =IF(M5=1,"대졸",IF(M5=2,"고졸","중졸")) -> 중졸
B6: 030101-7658823 | C6: 정형준 | D6: =MID(C6,2,1) -> 형 | E6: =REPLACE(C6,2,1,"X") -> 정X준 | I6: 2 | J6: =IF(I6=1,"XXX","YYY") -> YYY | M6: 2 | N6: =IF(M6=1,"대졸",IF(M6=2,"고졸","중졸")) -> 고졸
B7: 030101-7658824 | C7: 이춘식 | D7: =MID(C7,2,1) -> 춘 | E7: =REPLACE(C7,2,1,"X") -> 이X식 | I7: 2 | J7: =IF(I7=1,"XXX","YYY") -> YYY | M7: 3 | N7: =IF(M7=1,"대졸",IF(M7=2,"고졸","중졸")) -> 중졸
B8: 700101-1658825 | C8: 김수민 | D8: =MID(C8,2,1) -> 수 | E8: =REPLACE(C8,2,1,"X") -> 김X민 | I8: 1 | J8: =IF(I8=1,"XXX","YYY") -> XXX | M8: 2 | N8: =IF(M8=1,"대졸",IF(M8=2,"고졸","중졸")) -> 고졸
B9: 700101-1658826 | C9: 정형준 | D9: =MID(C9,2,1) -> 형 | E9: =REPLACE(C9,2,1,"X") -> 정X준 | I9: 1 | J9: =IF(I9=1,"XXX","YYY") -> XXX | M9: 1 | N9: =IF(M9=1,"대졸",IF(M9=2,"고졸","중졸")) -> 대졸
B10: 700101-1658827 | C10: 이춘식 | D10: =MID(C10,2,1) -> 춘 | E10: =REPLACE(C10,2,1,"X") -> 이X식 | I10: 2 | J10: =IF(I10=1,"XXX","YYY") -> YYY | M10: 1 | N10: =IF(M10=1,"대졸",IF(M10=2,"고졸","중졸")) -> 대졸
B11: 700101-1658828 | C11: 김수민 | D11: =MID(C11,2,1) -> 수 | E11: =REPLACE(C11,2,1,"X") -> 김X민 | I11: 2 | J11: =IF(I11=1,"XXX","YYY") -> YYY | M11: 2 | N11: =IF(M11=1,"대졸",IF(M11=2,"고졸","중졸")) -> 고졸
B12: 700101-1658829 | C12: 정형준 | D12: =MID(C12,2,1) -> 형 | E12: =REPLACE(C12,2,1,"X") -> 정X준 | I12: 1 | J12: =IF(I12=1,"XXX","YYY") -> XXX | M12: 3 | N12: =IF(M12=1,"대졸",IF(M12=2,"고졸","중졸")) -> 중졸
B13: 700101-1658830 | C13: 이춘식 | D13: =MID(C13,2,1) -> 춘 | E13: =REPLACE(C13,2,1,"X") -> 이X식 | I13: 1 | J13: =IF(I13=1,"XXX","YYY") -> XXX | M13: 2 | N13: =IF(M13=1,"대졸",IF(M13=2,"고졸","중졸")) -> 고졸
B14: 700101-1658831 | C14: 김수민 | D14: =MID(C14,2,1) -> 수 | E14: =REPLACE(C14,2,1,"X") -> 김X민 | I14: 2 | J14: =IF(I14=1,"XXX","YYY") -> YYY | M14: 3 | N14: =IF(M14=1,"대졸",IF(M14=2,"고졸","중졸")) -> 중졸
B15: 700101-1658832 | C15: 정형준 | D15: =MID(C15,2,1) -> 형 | E15: =REPLACE(C15,2,1,"X") -> 정X준 | I15: 2 | J15: =IF(I15=1,"XXX","YYY") -> YYY | M15: 3 | N15: =IF(M15=1,"대졸",IF(M15=2,"고졸","중졸")) -> 중졸
... B20: 700101-1658837 | C20: 김수민 | D20: =MID(C20,2,1) -> 수 | E20: =REPLACE(C20,2,1,"X") -> 김X민 | I20: 2 | J20: =IF(I20=1,"XXX","YYY") -> YYY | M20: 3 | N20: =IF(M20=1,"대졸",IF(M20=2,"고졸","중졸")) -> 중졸
B21: 700101-1658838 | C21: 정형준 | E21: =REPLACE(C21,2,1,"X") -> 정X준 | I21: 1 | J21: =IF(I21=1,"XXX","YYY") -> XXX | M21: 3 | N21: =IF(M21=1,"대졸",IF(M21=2,"고졸","중졸")) -> 중졸
B22: 700101-1658839 | C22: 이춘식 | E22: =REPLACE(C22,2,1,"X") -> 이X식 | I22: 2 | J22: =IF(I22=1,"XXX","YYY") -> YYY | M22: 3 | N22: =IF(M22=1,"대졸",IF(M22=2,"고졸","중졸")) -> 중졸
B23: 700101-1658840 | C23: 김수민 | E23: =REPLACE(C23,2,1,"X") -> 김X민 | I23: 2 | J23: =IF(I23=1,"XXX","YYY") -> YYY | M23: 3 | N23: =IF(M23=1,"대졸",IF(M23=2,"고졸","중졸")) -> 중졸
B24: 700101-1658841 | C24: 정형준 | E24: =REPLACE(C24,2,1,"X") -> 정X준 | I24: 1 | J24: =IF(I24=1,"XXX","YYY") -> XXX | M24: 3 | N24: =IF(M24=1,"대졸",IF(M24=2,"고졸","중졸")) -> 중졸
B25: 700101-1658842 | C25: 이춘식 | E25: =REPLACE(C25,2,1,"X") -> 이X식 | I25: 2 | J25: =IF(I25=1,"XXX","YYY") -> YYY | M25: 1 | N25: =IF(M25=1,"대졸",IF(M25=2,"고졸","중졸")) -> 대졸
B26: 700101-1658843 | C26: 김수민 | E26: =REPLACE(C26,2,1,"X") -> 김X민 | I26: 1 | J26: =IF(I26=1,"XXX","YYY") -> XXX | M26: 1 | N26: =IF(M26=1,"대졸",IF(M26=2,"고졸","중졸")) -> 대졸
B27: 700101-1658844 | C27: 정형준 | E27: =REPLACE(C27,2,1,"X") -> 정X준 | I27: 2 | J27: =IF(I27=1,"XXX","YYY") -> YYY | M27: 1 | N27: =IF(M27=1,"대졸",IF(M27=2,"고졸","중졸")) -> 대졸
B28: 700101-1658845 | C28: 이춘식 | E28: =REPLACE(C28,2,1,"X") -> 이X식 | M28: 2 | N28: =IF(M28=1,"대졸",IF(M28=2,"고졸","중졸")) -> 고졸
B29: 700101-1658846 | C29: 김수민 | E29: =REPLACE(C29,2,1,"X") -> 김X민 | M29: 3 | N29: =IF(M29=1,"대졸",IF(M29=2,"고졸","중졸")) -> 중졸
B30: 700101-1658847 | C30: 정형준 | E30: =REPLACE(C30,2,1,"X") -> 정X준
B31: 700101-1658848 | C31: 이춘식 | E31: =REPLACE(C31,2,1,"X") -> 이X식
B32: 700101-1658849 | C32: 김수민 | E32: =REPLACE(C32,2,1,"X") -> 김X민
B33: 700101-1658850 | C33: 정형준 | E33: =REPLACE(C33,2,1,"X") -> 정X준
B34: 700101-1658851 | C34: 이춘식 | E34: =REPLACE(C34,2,1,"X") -> 이X식
B35: 700101-1658852 | C35: 김수민 | E35: =REPLACE(C35,2,1,"X") -> 김X민
B36: 700101-1658853 | C36: 정형준 | E36: =REPLACE(C36,2,1,"X") -> 정X준
B37: 700101-1658854 | C37: 이춘식 | E37: =REPLACE(C37,2,1,"X") -> 이X식
B38: 700101-1658855 | C38: 김수민 | E38: =REPLACE(C38,2,1,"X") -> 김X민
B39: 700101-1658856 | C39: 정형준 | E39: =REPLACE(C39,2,1,"X") -> 정X준
B40: 700101-1658857 | C40: 이춘식 | E40: =REPLACE(C40,2,1,"X") -> 이X식
B41: 700101-1658858 | C41: 김수민 | E41: =REPLACE(C41,2,1,"X") -> 김X민
... B869: 700101-1659686 | C869: 김수민 | E869: =REPLACE(C869,2,1,"X") -> 김X민

Sheet 피벗
J3: 배열함수예제 (IF 없이)
C4: 품목 | D4: 지역 | E4: 단가(U$) | F4: 판매수량 | G4: 판매액(U$) | K4: LA | L4: 경남 | M4: 전남
C5: CD | D5: LA | E5: 76 | F5: 8 | G5: =E5*F5 -> 608 | J5: CD | K5: {=SUM(($C$5:$C$20=$J5)*($D$5:$D$20=K$4)*$G$5:$G$20)} -> 608 | L5: {=SUM(($C$5:$C$20=$J5)*($D$5:$D$20=L$4)*$G$5:$G$20)} -> 0 | M5: {=SUM(($C$5:$C$20=$J5)*($D$5:$D$20=M$4)*$G$5:$G$20)} -> 948
C6: USB | D6: 샌프란시스코 | E6: 543 | F6: 12 | G6: =E6*F6 -> 6516 | J6: USB | K6: {=SUM(($C$5:$C$20=$J6)*($D$5:$D$20=K$4)*$G$5:$G$20)} -> 0 | L6: {=SUM(($C$5:$C$20=$J6)*($D$5:$D$20=L$4)*$G$5:$G$20)} -> 2592 | M6: {=SUM(($C$5:$C$20=$J6)*($D$5:$D$20=M$4)*$G$5:$G$20)} -> 0
C7: 매모리 | D7: LA | E7: 145 | F7: 3 | G7: =E7*F7 -> 435 | J7: 키보드 | K7: {=SUM(($C$5:$C$20=$J7)*($D$5:$D$20=K$4)*$G$5:$G$20)} -> 0 | L7: {=SUM(($C$5:$C$20=$J7)*($D$5:$D$20=L$4)*$G$5:$G$20)} -> 912 | M7: {=SUM(($C$5:$C$20=$J7)*($D$5:$D$20=M$4)*$G$5:$G$20)} -> 0
C8: 키보드 | D8: 경남 | E8: 76 | F8: 12 | G8: =E8*F8 -> 912
C9: USB | D9: 경남 | E9: 432 | F9: 6 | G9: =E9*F9 -> 2592
C10: 그래픽카드 | D10: 경남 | E10: 234 | F10: 5 | G10: =E10*F10 -> 1170 | J10: 배열함수예제 (IF 포함)
C11: 모니터 | D11: LA | E11: 56 | F11: 23 | G11: =E11*F11 -> 1288 | K11: LA | L11: 경남 | M11: 전남
C12: 키보드 | D12: 경북 | E12: 234 | F12: 13 | G12: =E12*F12 -> 3042 | J12: CD | K12: {=SUM(IF(($C$5:$C$20=$J12)*($D$5:$D$20=K$11),$G$5:$G$20))} -> 608 | L12: {=SUM(IF(($C$5:$C$20=$J12)*($D$5:$D$20=L$11),$G$5:$G$20))} -> 0 | M12: {=SUM(IF(($C$5:$C$20=$J12)*($D$5:$D$20=M$11),$G$5:$G$20))} -> 948
C13: 모니터 | D13: 샌디에이고 | E13: 34 | F13: 11 | G13: =E13*F13 -> 374 | J13: USB | K13: {=SUM(IF(($C$5:$C$20=$J13)*($D$5:$D$20=K$11),$G$5:$G$20))} -> 0 | L13: {=SUM(IF(($C$5:$C$20=$J13)*($D$5:$D$20=L$11),$G$5:$G$20))} -> 2592 | M13: {=SUM(IF(($C$5:$C$20=$J13)*($D$5:$D$20=M$11),$G$5:$G$20))} -> 0
C14: CPU | D14: LA | E14: 54 | F14: 10 | G14: =E14*F14 -> 540 | J14: 키보드 | K14: {=SUM(IF(($C$5:$C$20=$J14)*($D$5:$D$20=K$11),$G$5:$G$20))} -> 0 | L14: {=SUM(IF(($C$5:$C$20=$J14)*($D$5:$D$20=L$11),$G$5:$G$20))} -> 912 | M14: {=SUM(IF(($C$5:$C$20=$J14)*($D$5:$D$20=M$11),$G$5:$G$20))} -> 0
C15: 키보드 | D15: 샌프란시스코 | E15: 65 | F15: 12 | G15: =E15*F15 -> 780
C16: CD | D16: 전남 | E16: 34 | F16: 12 | G16: =E16*F16 -> 408
C17: USB | D17: 제주 | E17: 43 | F17: 12 | G17: =E17*F17 -> 516
C18: CD | D18: 워싱턴 | E18: 433 | F18: 14 | G18: =E18*F18 -> 6062
C19: CD | D19: 전남 | E19: 45 | F19: 12 | G19: =E19*F19 -> 540
C20: USB | D20: 제주 | E20: 123 | F20: 12 | G20: =E20*F20 -> 1476

Sheet 회식비
A1: Data | I1: 기준정보
A2: 순번 | B2: 소속팀 | C2: 이름 | D2: 직급 | E2: 메뉴명 | F2: 금액(원) | G2: 본부 | I2: 본부 | J2: 팀 | L2: 본부 | M2: 금액(원)
A3: 1 | B3: 인사팀 | C3: 공영호 | D3: 부장 | E3: 치킨마요 | I3: 인사팀 | J3: 경영지원본부 | L3: 경영지원본부
A4: 2 | B4: 시설구매팀 | C4: 김성수 | D4: 부장 | E4: 치킨마요 | I4: 시설구매팀 | J4: 경영지원본부 | L4: 중부사업본부
A5: 3 | B5: 중부영업1팀 | C5: 이정호 | D5: 부장 | E5: 동백도시락 | I5: 중부영업1팀 | J5: 중부사업본부 | L5: 호남사업본부
A6: 4 | B6: 중부영업2팀 | C6: 박성진 | D6: 부장 | E6: 치킨마요 | I6: 중부영업2팀 | J6: 중부사업본부 | L6: 영남사업본부
A7: 5 | B7: 중부영업3팀 | C7: 김건우 | D7: 차장 | E7: 동백도시락 | I7: 중부영업3팀 | J7: 중부사업본부 | M7: =SUM(M3:M6) -> 0
A8: 6 | B8: 호남영업1팀 | C8: 최민서 | D8: 차장 | E8: 치킨제육도시락 | I8: 호남영업1팀 | J8: 호남사업본부
A9: 7 | B9: 호남영업2팀 | C9: 김서윤 | D9: 차장 | E9: 참치마요 | I9: 호남영업2팀 | J9: 호남사업본부 | L9: 메뉴명 | M9: 수량
A10: 8 | B10: 영남영업1팀 | C10: 최준혁 | D10: 차장 | E10: 치킨마요 | I10: 영남영업1팀 | J10: 영남사업본부 | L10: 치킨마요
A11: 9 | B11: 영남영업2팀 | C11: 김우진 | D11: 과장 | E11: 돈까스도련님도시락 | I11: 영남영업2팀 | J11: 영남사업본부 | L11: 참치마요
A12: 10 | B12: 인사팀 | C12: 이은경 | D12: 과장 | E12: 치킨제육도시락 | L12: 치킨제육도시락
A13: 11 | B13: 시설구매팀 | C13: 김영진 | D13: 과장 | E13: 치킨마요 | I13: 메뉴명 | J13: 단가(원) | L13: 돈까스도련님도시락
A14: 12 | B14: 중부영업1팀 | C14: 유병철 | D14: 과장 | E14: 돈까스도련님도시락 | I14: 치킨마요 | J14: 8500 | L14: 왕치킨마요
A15: 13 | B15: 중부영업2팀 | C15: 이상현 | D15: 대리 | E15: 진달래도시락 | I15: 참치마요 | J15: 9000 | L15: 동백도시락
A16: 14 | B16: 중부영업3팀 | C16: 오정훈 | D16: 대리 | E16: 왕치킨마요 | I16: 치킨제육도시락 | J16: 9500 | L16: 왕카레돈까스덮밥
A17: 15 | B17: 호남영업1팀 | C17: 이지영 | D17: 대리 | E17: 동백도시락 | I17: 돈까스도련님도시락 | J17: 8900 | L17: 진달래도시락
A18: 16 | B18: 호남영업2팀 | C18: 김도현 | D18: 사원 | E18: 메가고기고기 | I18: 왕치킨마요 | J18: 12000 | L18: 메가고기고기
A19: 17 | B19: 영남영업1팀 | C19: 최수빈 | D19: 사원 | E19: 왕카레돈까스덮밥 | I19: 동백도시락 | J19: 9500
A20: 18 | B20: 영남영업2팀 | C20: 이진우 | D20: 사원 | E20: 진달래도시락 | I20: 왕카레돈까스덮밥 | J20: 11000
A21: 19 | B21: 인사팀 | C21: 김정수 | D21: 사원 | E21: 메가고기고기 | I21: 진달래도시락 | J21: 9000
A22: 20 | B22: 시설구매팀 | C22: 이예진 | D22: 사원 | E22: 치킨제육도시락 | I22: 메가고기고기 | J22: 8900
E23: =COUNTA(E3:E22) -> 20 | F23: =SUM(F3:F22) -> 0
B24: countifs, sumifs
C26: 경영지원본부 | D26: 중부사업본부 | E26: 호남사업본부 | F26: 영남사업본부
B27: 부장
B28: 차장
B29: 과장
B30: 대리

Sheet VLOOKUP
B5: 봄 | C5: 여름 | D5: 가을 | E5: 겨울 | I5: 여름
A6: ICE아메리카노 | B6: 4300 | C6: 4500 | D6: 4600 | E6: 4700 | J6: 44669 | K6: 수량 | L6: 단가 | M6: 합계
A7: 아메리카노 | B7: 4300 | C7: 3000 | D7: 4500 | E7: 3600 | J7: ICE아메리카노 | K7: 14 | M7: =IF(L7=" "," ",K7*L7) -> 0
A8: 라떼 | B8: 4500 | C8: 4500 | D8: 4300 | E8: 2500 | J8: 아메리카노 | K8: 31 | M8: =IF(L8=" "," ",K8*L8) -> 0
A9: 주스 | B9: 4500 | C9: 7000 | D9: 4300 | E9: 4500 | J9: 라떼 | K9: 23 | M9: =IF(L9=" "," ",K9*L9) -> 0
A10: 딸기스무디 | B10: 3400 | C10: 7500 | D10: 3400 | E10: 3400 | J10: 딸기스무디 | K10: 12 | M10: =IF(L10=" "," ",K10*L10) -> 0
A11: 프레인 스무디 | B11: 2300 | C11: 4500 | D11: 4300 | E11: 2500 | J11: 프레인 스무디 | K11: 13 | M11: =IF(L11=" "," ",K11*L11) -> 0
A12: 초토스무디 | B12: 6500 | C12: 7000 | D12: 4300 | E12: 6500 | J12: 토마토쥬스 | K12: 21 | M12: =IF(L12=" "," ",K12*L12) -> 0
A13: 토마토쥬스 | B13: 4900 | C13: 5700 | D13: 6700 | E13: 6300 | J13: 합계 | M13: =SUM(M7:M12) -> 0

Sheet HLOOKUP
J3: 여름
B4: ICE아메리카노 | C4: 아메리카노 | D4: 라떼 | E4: 수무디 | F4: 주스 | J4: 44491 | L4: 수량 | M4: 단가 | N4: 합계
A5: 봄 | B5: 3900 | C5: 2500 | D5: 3000 | E5: 6500 | F5: 7000 | K5: ICE아메리카노 | L5: 4 | N5: =L5*M5 -> 0
A6: 여름 | B6: 4500 | C6: 1500 | D6: 2200 | E6: 6000 | F6: 7200 | K6: 아메리카노 | L6: 3 | N6: =L6*M6 -> 0
A7: 가을 | B7: 4800 | C7: 2500 | D7: 3500 | E7: 5500 | F7: 7000 | K7: 라떼 | L7: 6 | N7: =L7*M7 -> 0
A8: 겨울 | B8: 4500 | C8: 3000 | D8: 3000 | E8: 6000 | F8: 6500 | K8: 수무디 | L8: 4 | N8: =L8*M8 -> 0
K9: 주스 | L9: 12 | N9: =L9*M9 -> 0
K10: 합계 | N10: =SUM(N5:N9) -> 0

Sheet 정보보호
A1: 회사명 | B1: 성명 | C1: 자택주소 | D1: 휴대폰번호 | E1: 회사주소 | F1: 회사전화번호 | G1: 고객요청(이셀만 풀기) | H1: 고객등급(이셀만 막기)
A2: (주)석수와퓨리스 | B2: 강균성 | C2: 경기도 고양시 일산서구 주엽2동 19 | D2: 010-3428-4344 | E2: 서울시 종로구 관철동 258 구몬빌딩 10층 | F2: 054-9199-1306 | G2: hhh
A3: (주)대화유통 | B3: 강미경 | C3: 서울시 서초구 염곡동 234-12 | D3: 010-2290-1894 | E3: 경기도 평택시 고덕면 율포리 539-5 | F3: 051-4610-9221
A4: (주)생생식품유통 | B4: 강민도 | C4: 경기도 하남시 신장1동 42-38 SU빌라 75호 | D4: 010-4768-8192 | E4: 서울시 서초구 서초2동 1376-1 | F4: 051-4771-8571
A5: (주)강산베어스 | B5: 고경희 | C5: 서울시 중랑구 면목7동 6413 | D5: 010-3552-5749 | E5: 서울시 동대문구 신설동 96-48 대상빌딩 | F5: 032-4143-4094
A6: (주)PS스포츠 | B6: 구선옥 | C6: 서울시 영등포구 당산2동 87 | D6: 010-2830-3317 | E6: 서울시 중구 신당동 171 | F6: 02-2836-3640
A7: (주)싸이버스카이 | B7: 구유정 | C7: 서울시 서초구 잠원동 15720 | D7: 010-8516-9570 | E7: 서울 용산구 한강로3가 40-1 철도회관 6 | F7: 051-1611-3683
A8: (주)산뜻페인트 | B8: 권민정 | C8: 서울시 용산구 우산단로 4 | D8: 010-6620-9356 | E8: 서울 송파구 문정동 70-5 | F8: 051-3609-2149
A9: (주)신라건설 | B9: 김경락 | C9: 서울시 중구 장충동2가 1995 | D9: 010-2763-4079 | E9: 서울 종로구 신문로1가 57 금호빌딩 16층 | F9: 051-9494-7107
A10: (주)삼홍사 | B10: 김기란 | C10: 서울시 강남구 삼성동 강남빌라 3-3 | D10: 010-5682-2036 | E10: 서울시 용산구 한강로 3가 40-134 | F10: 051-1113-8209
A11: (주)미광이티씨 | B11: 김대식 | C11: 서울시 광진구 구의동 강변B 24호 | D11: 010-4804-2419 | E11: 서울 중구 소공동 51 해운센타빌딩 신관 | F11: 051-7536-7307
A12: (주)드림익스프레스 | B12: 김미선 | C12: 서울시 종로구 동숭4가길 동숭상가 B동 138 | D12: 010-7976-9145 | E12: 경기도 안양시 만안구 박달동 615 | F12: 051-3592-2818
A13: ㈜세일백화점 | B13: 김민호 | C13: 서울시 중구 중림동 200 27 | D13: 010-4485-7423 | E13: lll | F13: 031-7423-7999
A14: (주)백두 | B14: 김보성 | C14: 서울시 성동구 옥수동 4557 | D14: 010-4304-9766 | E14: 서울 노원구 월계동 447-1번지 광운대학교 | F14: 051-1101-5993
... A383: (주)디에이치클럽닷컴 | B383: 함진경 | C383: 서울시 중구 남산동2가 4971 | D383: 010-3740-4272 | E383: 서울 강남구 대치동 891-10 동부금융센터 | F383: 051-5196-5549

Sheet 절대참조
B7: 달러 | C7: 원화 | E7: 환율
B8: 1000 | C8: =B8*$F$9 -> 1430000 | E8: U$ | F8: W$
B9: 325 | C9: =B9*$F$9 -> 464750 | E9: 1 | F9: 1430 | G9: 45791
B10: 500 | C10: =B10*$F$9 -> 715000 | E10: 1 | F10: 1234 | G10: 45779
B11: 567 | C11: =B11*$F$9 -> 810810 | E11: 1 | F11: 1232 | G11: 45780
B12: 540 | C12: =B12*$F$9 -> 772200 | E12: 1 | F12: 1200 | G12: 45781
B13: 2000 | C13: =B13*$F$9 -> 2860000 | E13: 1 | F13: 1324 | G13: 45782
B14: 3000 | C14: =B14*$F$9 -> 4290000 | E14: 1 | F14: 1345 | G14: 45783
C15: =SUM(C8:C14) -> 11342760 | E15: 1 | F15: 1300 | G15: 45789
B20: 빈셀에 데이터 입력시 자동으로 테두리가 채워짐: 조건부서식 =$b8<>"" 서식넣기

Sheet 고급필터
B1: 문제. [표1]의 대학 목록 중 "과학대학" 으로 끝나면서, 학과명에 "복지" 단어를 포함하고 있는 데이터의
C2: '이름, 학과, 학점' 필드만 결과로 추출하시오. (And, Right, Find 함수 사용)
C3: 조건은 [G6:G7] 영역에 입력.
C4: 결과는 [G9] 부터 입력되도록 설정.
B5: [표1]
B6: 이름 | C6: 대학 | D6: 학과 | E6: 학점
B7: 김함바 | C7: 사회과학대학 | D7: 사회복지학과 | E7: A
B8: 박헨리 | C8: 사회과학대학 | D8: 사회학과 | E8: B+
B9: 김골든 | C9: 공과대학 | D9: 소프트웨어공학과 | E9: A
B10: 이정우 | C10: 사범대학 | D10: 국어교육과 | E10: A+
B11: 송혜수 | C11: 공과대학 | D11: 컴퓨터공학과 | E11: C
B12: 서유진 | C12: 사회과학대학 | D12: 사회복지학과 | E12: B-
B13: 김써니 | C13: 공과대학 | D13: 소프트웨어공학과 | E13: A-
B14: 지율무 | C14: 공과대학 | D14: 컴퓨터공학과 | E14: C+
B15: 이효진 | C15: 사범대학 | D15: 국어교육과 | E15: A
B16: 박정재 | C16: 사범대학 | D16: 국어교육과 | E16: B
B17: 최승원 | C17: 사회과학대학 | D17: 심리학과 | E17: B
... B21: 송자영 | C21: 사회과학대학 | D21: 심리학과 | E21: B-

Sheet 프로시져
A1: 1 | B1: 문제. [표1] 을 참조하여 BMI를 출력하시오.
B2: 식 : BMI=체중 / ( 키/100) ^ 2
B3: (select case 사용)
I4: [표1]
I5: 저체중 | J5: 20 미만
I6: 정상 | J6: 20 - 24
I7: 과체중 | J7: 25 - 29
B8: 이름 | C8: 체중 | D8: 키 | E8: BMI | I8: 비만 | J8: 30 이상
B9: 김함바 | C9: 60 | D9: 170 | E9: {=fn비만도1(C9,D9)} -> #NAME?
B10: 박헨리 | C10: 70 | D10: 180
B11: 김골든 | C11: 80 | D11: 160
B12: 이정우 | C12: 90 | D12: 170
B13: 송혜수 | C13: 75 | D13: 180
B14: 서유진 | C14: 80 | D14: 170
B15: 김써니 | C15: 85 | D15: 180
B16: 지율무 | C16: 55 | D16: 160
B17: 이효진 | C17: 60 | D17: 170
B18: 박정재 | C18: 65 | D18: 180
B19: 최승원 | C19: 90 | D19: 170

Sheet 배열함수와VBA
B1: [표1]
B2: 이름 | C2: 학과 | D2: 전필 | E2: 전선 | F2: 교필 | H2: 문제: 학과별 전필, 전선, 교필 점수가 가장 큰 학생의 '이름'을
B3: 김함바 | C3: 컴퓨터공학 | D3: 98 | E3: 88 | F3: 80 | H3: [표2] 영역에 표시.
B4: 박헨리 | C4: 독어독문학 | D4: 89 | E4: 99 | F4: 63 | H4: (INDEX, MATCH, MAX 함수 이용한 배열 수식)
B5: 김골든 | C5: 수의학 | D5: 82 | E5: 55 | F5: 77
B6: 이정우 | C6: 디자인 | D6: 64 | E6: 99 | F6: 99 | H6: [표2]
B7: 송혜수 | C7: 컴퓨터공학 | D7: 51 | E7: 44 | F7: 81 | H7: 학과 | I7: 전필 | J7: 전선 | K7: 교필 | M7: 학과 | N7: 전필 | O7: 전선 | P7: 교필
B8: 서유진 | C8: 독어독문학 | D8: 93 | E8: 66 | F8: 86 | H8: 컴퓨터공학 | M8: 컴퓨터공학 | N8: {=MAX(($H8=$C$3:$C$14)*(D$3:D$14))} -> 99
B9: 김써니 | C9: 수의학 | D9: 86 | E9: 99 | F9: 93 | H9: 독어독문학 | M9: 독어독문학
B10: 지율무 | C10: 디자인 | D10: 72 | E10: 55 | F10: 100 | H10: 수의학 | M10: 수의학
B11: 이효진 | C11: 컴퓨터공학 | D11: 99 | E11: 66 | F11: 64 | H11: 디자인 | M11: 디자인
B12: 박정재 | C12: 독어독문학 | D12: 77 | E12: 88 | F12: 82
B13: 최승원 | C13: 수의학 | D13: 99 | E13: 55 | F13: 89 | H13: =INDEX( 가져올값이 있는 범위, 행번호, 열번호 )
B14: 공두나 | C14: 디자인 | D14: 80 | E14: 77 | F14: 98 | H14: =MATCH( 찾을값 , 값범위 , 방식 )
H15: =MAX( 값범위 )
L21: {=INDEX($B$3:$B$14,MATCH(MAX(($H8=$C$3:$C$14)*(D$3:D$14)),($H8=$C$3:$C$14)*(D$3:D$14),0),1)} -> 이효진

Sheet 조건부서식
B2: 문제. 면접일이 화요일, 금요일 인 행 전체에 '노랑'채우기 '빨간'글꼴 '굵게' 설정하시오.
B3: ▶ Weekday 함수 사용. (단, 월요일이 1인 방식)
B4: ▶ 수식을 이용하여 서식을 지정할 셀 결정을 이용.
B6: 성명 | C6: 학과 | D6: 주소 | E6: 전화번호 | F6: 면접일 | G6: 전필 | H6: 전선 | I6: 교필 | J6: 교선 | K6: 합계 | L6: 평균
B7: 김함바 | C7: 컴퓨터공학 | D7: 서울특별시 | E7: 02-111-1111 | F7: 44562 | G7: 98 | H7: 88 | I7: 80 | J7: 77 | K7: 343 | L7: 85.8
B8: 박헨리 | C8: 독어독문학 | D8: 강원도 | E8: 033-222-2222 | F8: 44593 | G8: 89 | H8: 99 | I8: 63 | J8: 55 | K8: 306 | L8: 76.5
B9: 김골든 | C9: 수의학 | D9: 경기도 | E9: 031-333-3333 | F9: 44621 | G9: 82 | H9: 55 | I9: 77 | J9: 88 | K9: 302 | L9: 75.5
B10: 이정우 | C10: 디자인 | D10: 충청도 | E10: 043-555-5555 | F10: 44652 | G10: 64 | H10: 99 | I10: 99 | J10: 66 | K10: 328 | L10: 82
B11: 송혜수 | C11: 컴퓨터공학 | D11: 서울특별시 | E11: 02-777-7777 | F11: 44682 | G11: 51 | H11: 44 | I11: 81 | J11: 55 | K11: 231 | L11: 57.8
B12: 서유진 | C12: 독어독문학 | D12: 강원도 | E12: 033-888-8888 | F12: 44713 | G12: 93 | H12: 66 | I12: 86 | J12: 99 | K12: 344 | L12: 86
B13: 김써니 | C13: 수의학 | D13: 경기도 | E13: 031-999-9999 | F13: 44743 | G13: 86 | H13: 99 | I13: 93 | J13: 66 | K13: 344 | L13: 86
B14: 지율무 | C14: 디자인 | D14: 충청도 | E14: 043-001-0001 | F14: 44774 | G14: 72 | H14: 55 | I14: 51 | J14: 44 | K14: 222 | L14: 55.5
B15: 이효진 | C15: 컴퓨터공학 | D15: 서울특별시 | E15: 02-002-0002 | F15: 44805 | G15: 99 | H15: 66 | I15: 64 | J15: 99 | K15: 328 | L15: 82
B16: 박정재 | C16: 독어독문학 | D16: 강원도 | E16: 033-003-0003 | F16: 44835 | G16: 77 | H16: 88 | I16: 82 | J16: 55 | K16: 302 | L16: 75.5
B17: 최승원 | C17: 수의학 | D17: 경기도 | E17: 031-004-0004 | F17: 44866 | G17: 63 | H17: 55 | I17: 89 | J17: 99 | K17: 306 | L17: 76.5
B18: 공두나 | C18: 디자인 | D18: 충청도 | E18: 043-005-0005 | F18: 44896 | G18: 80 | H18: 77 | I18: 98 | J18: 88 | K18: 343 | L18: 85.8
B20: =WEEKDAY( 날짜 , 방식 ) | E20: 1: 일=1
E21: 2: 월=1
E22: 3: 월=0

Sheet 감독시간표
B4: 2024학년도 1학기 중간고사 감독표 | AM4: [안내사항] *꼭 확인 부탁드려요!* 1. 감독 순서나 시험실을 교체해야 하실 경우 반드시 연구부에 확인 바랍니다. 2. 시험 감독 중 학생들의 민원 소지가 있는 행위에 유의 바랍니다. 3. 시험 시작 전 반드시 부정행위에 대해 안내 부탁드리며, 시험 중 화장실 용무 등을 이유로 시험실을 나갈 경우 부감독 선생님께서 이동 및 지도 부탁드립니다. 4. 자습 감독 시 학생 무단 이동 및 대기실 이탈이 없도록 지도 부탁드립니다. 특히 다른 학년이나 학급에서 시험을 보는 경우 대기실 밖으로 이탈하지 않도록 지도 부탁드립니다. 5. 사회과실과 미술실에는 수업교구와 기자재가 있으므로 학생들이 사용하지 못하도록 안내 부탁드립니다. 6. 자습 감독 등에 연구부 지원이 가능하므로 지도 및 감독 시 어려움이 생기시면 알려주시기 바랍니다!
F6: 1 | G6: 1 | H6: 1 | I6: 1 | K6: 1 | L6: 2 | M6: 2 | N6: 2 | O6: 2 | P6: 2 | Q6: 2 | S6: 2 | Y6: 3 | Z6: 3 | AA6: 3 | AB6: 3 | AC6: 3 | AD6: 3 | AE6: 3
B7: 일자 | C7: 교시 | D7: 감독 | E7: 1학년 | L7: 2학년 | T7: 시험실/자습실 | W7: 자습실 | Y7: 3학년 | AF7: 시험실/자습실 | AJ7: 자습반
E8: 1-1 | F8: 1-2 | G8: 1-3 | H8: 1-4 | I8: 1-5 | J8: 1-6 | K8: 1-7 | L8: 2-1 | M8: 2-2 | N8: 2-3 | O8: 2-4 | P8: 2-5 | Q8: 2-6 | R8: 2-7 | S8: 2-8 | T8: 301 | U8: 302 | V8: 303 | W8: AI실 | X8: 도서실 | Y8: 3-1 | Z8: 3-2 | AA8: 3-3 | AB8: 3-4 | AC8: 3-5 | AD8: 3-6 | AE8: 3-7 | AF8: 301 | AG8: 302 | AH8: 303 | AI8: 304 | AJ8: AI실 | AK8: 도서실
B9: 4/25 (목) | C9: 1교시 | D9: =32+0+2+2+4 -> 40 | E9: 자습 | L9: 문학 | Y9: 독서
D10: 정 | E10: 14 | I10: 10 | L10: 41 | M10: 39 | N10: 17 | O10: 31 | P10: 11 | Q10: 48 | R10: 12 | S10: 46 | Y10: 28 | Z10: 6 | AA10: 5 | AB10: 43 | AC10: 32 | AD10: 29 | AE10: 44
C11: 09:00~09:50 | D11: 부 | L11: 2 | M11: 50 | N11: 47 | O11: 45 | P11: 26 | Q11: 19 | R11: 13 | S11: 34 | Y11: 27 | Z11: 20 | AA11: 22 | AB11: 36 | AC11: 52 | AD11: 51 | AE11: 33
C12: 2교시 | D12: =6+4 -> 10 | E12: 자습 | L12: 자습 | Y12: 자습
D13: 정 | E13: 11 | I13: 41 | L13: 31 | P13: 12 | Y13: 18 | AC13: 37
C14: 10:20~11:10 | D14: 부
C15: 3교시 | D15: =26+2+1+1+4 -> 34 | E15: 영어 | L15: 자습 | T15: 정치와 법 | Y15: 자습 | AI15: 세계사
D16: 정 | E16: 42 | F16: 43 | G16: 28 | H16: 45 | I16: 38 | J16: 1 | K16: 26 | L16: 15 | P16: 7 | T16: 14 | U16: 48 | V16: 30 | Y16: 32 | AC16: 4 | AI16: 33
C17: 11:40~12:30 | D17: 부 | E17: 19 | F17: 3 | G17: 25 | H17: 40 | I17: 44 | J17: 31 | K17: 9 | T17: 46 | U17: 34 | V17: 27 | AI17: 12
B18: 4/26 (금) | C18: 1교시 | D18: =41+1+1+2+1+0+2+5 -> 53 | E18: 한국사 | L18: 지구과학Ⅰ | P18: 세계지리 | Y18: 경수 | Z18: 진로영어 | AD18: 심화수학Ⅰ
D19: 정 | E19: 47 | F19: 22 | G19: 26 | H19: 2 | I19: 50 | J19: 37 | K19: 46 | L19: 43 | M19: 7 | N19: 25 | O19: 15 | P19: 9 | Q19: 6 | R19: 42 | S19: 30 | Y19: 44 | Z19: 36 | AA19: 40 | AB19: 39 | AC19: 34 | AD19: 38 | AE19: 45
C20: 09:00~09:50 | D20: 부 | E20: 18 | F20: 1 | G20: 48 | H20: 27 | I20: 52 | J20: 20 | K20: 4 | L20: 5 | M20: 24 | N20: 51 | O20: 11 | P20: 29 | Q20: 14 | R20: 10 | S20: 8 | Y20: 17 | Z20: 32 | AB20: 35 | AD20: 53
C21: 2교시 | D21: =6+6 -> 12 | E21: 자습 | L21: 자습 | Y21: 자습
D22: 정 | E22: 11 | I22: 31 | L22: 13 | P22: 30 | Y22: 20 | AC22: 3
C23: 10:20~11:10 | D23: 부
C24: 3교시 | D24: =30+3+1+2+7 -> 43 | E24: 통합과학 | L24: 자습 | T24: 화학Ⅰ | Y24: 윤리와 사상 | AJ24: 자습
D25: 정 | E25: 4 | F25: 18 | G25: 27 | H25: 11 | I25: 40 | J25: 47 | K25: 33 | L25: 19 | P25: 22 | T25: 37 | U25: 3 | V25: 31 | Y25: 35 | Z25: 9 | AA25: 25 | AJ25: 34 | AK25: 38
C26: 11:40~12:30 | D26: 부 | E26: 29 | F26: 45 | G26: 43 | H26: 52 | I26: 39 | J26: 2 | K26: 28 | T26: 38 | U26: 42 | V26: 8 | Y26: 30 | Z26: 50 | AA26: 32
B27: 4/29 (월) | C27: 1교시 | D27: =44+2+3+1+1+3 -> 54 | E27: 수학 | L27: 수학Ⅰ | Y27: 미적분 | AF27: 수학과제탐구
D28: 정 | E28: 8 | F28: 20 | G28: 53 | H28: 54 | I28: 25 | J28: 41 | K28: 48 | L28: 46 | M28: 15 | N28: 42 | O28: 7 | P28: 44 | Q28: 30 | R28: 34 | S28: 6 | AA28: 39 | AB28: 9 | AC28: 45 | AF28: 50 | AG28: 40 | AH28: 38 | AI28: 32
C29: 09:00~09:50 | D29: 부 | E29: 49 | F29: 21 | G29: 5 | H29: 22 | I29: 51 | J29: 23 | K29: 24 | L29: 1 | M29: 37 | N29: 4 | O29: 28 | P29: 18 | Q29: 3 | R29: 29 | S29: 47 | AA29: 10 | AB29: 35 | AC29: 36 | AF29: 14 | AG29: 13 | AH29: 17 | AI29: 52
C30: 2교시 | D30: =6+3 -> 9 | E30: 자습 | L30: 자습 | Y30: 자습
D31: 정 | E31: 2 | I31: 33 | L31: 17 | P31: 41 | Y31: 21 | AC31: 8
C32: 10:20~11:10 | D32: 부
C33: 3교시 | D33: =34+3+1+1+3 -> 42 | E33: 통합사회 | L33: 생활과 윤리 | W33: 자습 | Y33: 자습 | AF33: 한국지리
D34: 정 | E34: 10 | F34: 15 | G34: 33 | H34: 29 | I34: 13 | J34: 26 | K34: 19 | L34: 32 | M34: 27 | N34: 34 | O34: 35 | P34: 37 | W34: 1 | X34: 6 | Y34: 25 | AC34: 39 | AF34: 14 | AG34: 7 | AH34: 36
C35: 11:40~12:30 | D35: 부 | E35: 12 | F35: 45 | G35: 46 | H35: 51 | I35: 40 | J35: 49 | K35: 23 | L35: 47 | M35: 48 | N35: 43 | O35: 39 | P35: 41 | AF35: 52 | AG35: 42 | AH35: 21
C36: 1교시 | D36: =6+2 -> 8 | E36: 자습 | L36: 자습 | Y36: 자습
B37: 4/30 (화) | D37: 정 | E37: 16 | I37: 50 | L37: 46 | P37: 47 | Y37: 36 | AC37: 35
C38: 09:00~09:50 | D38: 부
C39: 2교시 | D39: =44+2+2+2+2 -> 52 | E39: 국어 | L39: 영어Ⅰ | Y39: 영어 독해와 작문
D40: 정 | E40: 28 | F40: 17 | G40: 18 | H40: 8 | I40: 24 | J40: 27 | K40: 12 | L40: 19 | M40: 4 | N40: 10 | O40: 5 | P40: 20 | Q40: 21 | R40: 13 | S40: 22 | Y40: 1 | Z40: 29 | AA40: 2 | AB40: 35 | AC40: 36 | AD40: 3 | AE40: 47
C41: 10:20~11:10 | D41: 부 | E41: 44 | F41: 42 | G41: 43 | H41: 23 | I41: 16 | J41: 48 | K41: 46 | L41: 26 | M41: 15 | N41: 7 | O41: 37 | P41: 38 | Q41: 49 | R41: 6 | S41: 40 | Y41: 34 | Z41: 33 | AA41: 30 | AB41: 51 | AC41: 9 | AD41: 41 | AE41: 50
C42: 3교시 | D42: =6+2 -> 8 | E42: 자습 | L42: 자습 | Y42: 자습
D43: 정 | E43: 48 | I43: 45 | L43: 42 | P43: 5 | Y43: 40 | AC43: 44
C44: 11:40~12:30 | D44: 부
...

Sheet 감독 순번
B2: 2024. 감독 순번 및 통계
B3: 1학기 | D3: 중간고사 | H3: 기말고사 | L3: 1학기 누계 | P3: 비고
B4: 감독번호 | C4: 감독교사 | D4: 정 | E4: 부 | F4: 자습 | G4: 누계 | H4: 정 | I4: 부 | J4: 자습 | K4: 누계 | L4: 정 | M4: 부 | N4: 자습 | O4: 누계
B5: 1 | C5: =[1]감독시간표!E52 -> 임웅묵 | D5: =COUNTIF([1]감독시간표!$L$10:$S$10,'[1]감독 순번'!B5)+COUNTIF([1]감독시간표!$Y$10:$AE$10,'[1]감독 순번'!B5)+COUNTIF([1]감독시간표!$E$16:$K$16,'[1]감독 순번'!B5)+COUNTIF([1]감독시간표!$T$16:$V$16,'[1]감독 순번'!B5)+COUNTIF([1]감독시간표!$AI$16,'[1]감독 순번'!B5)+COUNTIF([1]감독시간표!$E$19:$S$19,'[1]감독 순번'!B5)+COUNTIF([1]감독시간표!$Y$19:$AE$19,'[1]감독 순번'!B5)+COUNTIF([1]감독시간표!$E$25:$K$25,'[1]감독 순번'!B5)+COUNTIF([1]감독시간표!$T$25:$V$25,'[1]감독 순번'!B5)+COUNTIF([1]감독시간표!$Y$25:$AA$25,'[1]감독 순번'!B5)+COUNTIF([1]감독시간표!$E$28:$S$28,'[1]감독 순번'!B5)+COUNTIF([1]감독시간표!$AA$28:$AC$28,'[1]감독 순번'!B5)+COUNTIF([1]감독시간표!$AF$28:$AI$28,'[1]감독 순번'!B5)+COUNTIF([1]감독시간표!$E$34:$P$34,'[1]감독 순번'!B5)+COUNTIF([1]감독시간표!$AF$34:$AH$34,'[1]감독 순번'!B5)+COUNTIF([1]감독시간표!$E$40:$S$40,'[1]감독 순번'!B5)+COUNTIF([1]감독시간표!$Y$40:$AE$40,'[1]감독 순번'!B5)+COUNTIF([1]감독시간표!$E$46:$Q$46,'[1]감독 순번'!B5)+COUNTIF([1]감독시간표!$Y$46:$AC$46,'[1]감독 순번'!B5) -> #VALUE! | E5: =COUNTIF([1]감독시간표!$L$11:$S$11,'[1]감독 순번'!B5)+COUNTIF([1]감독시간표!$Y$11:$AE$11,'[1]감독 순번'!B5)+COUNTIF([1]감독시간표!$E$17:$K$17,'[1]감독 순번'!B5)+COUNTIF([1]감독시간표!$T$17:$V$17,'[1]감독 순번'!B5)+COUNTIF([1]감독시간표!$AI$17,'[1]감독 순번'!B5)+COUNTIF([1]감독시간표!$E$20:$S$20,'[1]감독 순번'!B5)+COUNTIF([1]감독시간표!$Y$20:$AE$20,'[1]감독 순번'!B5)+COUNTIF([1]감독시간표!$E$26:$K$26,'[1]감독 순번'!B5)+COUNTIF([1]감독시간표!$T$26:$V$26,'[1]감독 순번'!B5)+COUNTIF([1]감독시간표!$Y$26:$AA$26,'[1]감독 순번'!B5)+COUNTIF([1]감독시간표!$E$29:$S$29,'[1]감독 순번'!B5)+COUNTIF([1]감독시간표!$AA$29:$AC$29,'[1]감독 순번'!B5)+COUNTIF([1]감독시간표!$AF$29:$AI$29,'[1]감독 순번'!B5)+COUNTIF([1]감독시간표!$E$35:$P$35,'[1]감독 순번'!B5)+COUNTIF([1]감독시간표!$AF$35:$AH$35,'[1]감독 순번'!B5)+COUNTIF([1]감독시간표!$E$41:$S$41,'[1]감독 순번'!B5)+COUNTIF([1]감독시간표!$Y$41:$AE$41,'[1]감독 순번'!B5)+COUNTIF([1]감독시간표!$E$47:$Q$47,'[1]감독 순번'!B5)+COUNTIF([1]감독시간표!$Y$47:$AC$47,'[1]감독 순번'!B5) -> #VALUE! | F5: =COUNTIF([1]감독시간표!$E$10:$K$11,'[1]감독 순번'!B5)+COUNTIF([1]감독시간표!$E$13:$S$14,'[1]감독 순번'!B5)+COUNTIF([1]감독시간표!$Y$13:$AE$14,'[1]감독 순번'!B5)+COUNTIF([1]감독시간표!$L$16:$S$17,'[1]감독 순번'!B5)+COUNTIF([1]감독시간표!$Y$16:$AE$17,'[1]감독 순번'!B5)+COUNTIF([1]감독시간표!$E$22:$S$23,'[1]감독 순번'!B5)+COUNTIF([1]감독시간표!$Y$22:$AE$23,'[1]감독 순번'!B5)+COUNTIF([1]감독시간표!$L$25:$S$26,'[1]감독 순번'!B5)+COUNTIF([1]감독시간표!$AJ$25:$AK$26,'[1]감독 순번'!B5)+COUNTIF([1]감독시간표!$E$31:$S$32,'[1]감독 순번'!B5)+COUNTIF([1]감독시간표!$Y$31:$AE$32,'[1]감독 순번'!B5)+COUNTIF([1]감독시간표!$W$34:$AE$35,'[1]감독 순번'!B5)+COUNTIF([1]감독시간표!$E$37:$S$38,'[1]감독 순번'!B5)+COUNTIF([1]감독시간표!$Y$37:$AE$38,'[1]감독 순번'!B5)+COUNTIF([1]감독시간표!$E$43:$S$44,'[1]감독 순번'!B5)+COUNTIF([1]감독시간표!$Y$43:$AE$44,'[1]감독 순번'!B5)+COUNTIF([1]감독시간표!$X$46,'[1]감독 순번'!B5)+COUNTIF([1]감독시간표!$AG$46,'[1]감독 순번'!B5) -> #VALUE! | G5: =SUM(D5:F5) -> #VALUE!
B6: 2 | C6: =[1]감독시간표!E53 -> 김미정 | D6: =COUNTIF([1]감독시간표!$L$10:$S$10,'[1]감독 순번'!B6)+COUNTIF([1]감독시간표!$Y$10:$AE$10,'[1]감독 순번'!B6)+COUNTIF([1]감독시간표!$E$16:$K$16,'[1]감독 순번'!B6)+COUNTIF([1]감독시간표!$T$16:$V$16,'[1]감독 순번'!B6)+COUNTIF([1]감독시간표!$AI$16,'[1]감독 순번'!B6)+COUNTIF([1]감독시간표!$E$19:$S$19,'[1]감독 순번'!B6)+COUNTIF([1]감독시간표!$Y$19:$AE$19,'[1]감독 순번'!B6)+COUNTIF([1]감독시간표!$E$25:$K$25,'[1]감독 순번'!B6)+COUNTIF([1]감독시간표!$T$25:$V$25,'[1]감독 순번'!B6)+COUNTIF([1]감독시간표!$Y$25:$AA$25,'[1]감독 순번'!B6)+COUNTIF([1]감독시간표!$E$28:$S$28,'[1]감독 순번'!B6)+COUNTIF([1]감독시간표!$AA$28:$AC$28,'[1]감독 순번'!B6)+COUNTIF([1]감독시간표!$AF$28:$AI$28,'[1]감독 순번'!B6)+COUNTIF([1]감독시간표!$E$34:$P$34,'[1]감독 순번'!B6)+COUNTIF([1]감독시간표!$AF$34:$AH$34,'[1]감독 순번'!B6)+COUNTIF([1]감독시간표!$E$40:$S$40,'[1]감독 순번'!B6)+COUNTIF([1]감독시간표!$Y$40:$AE$40,'[1]감독 순번'!B6)+COUNTIF([1]감독시간표!$E$46:$Q$46,'[1]감독 순번'!B6)+COUNTIF([1]감독시간표!$Y$46:$AC$46,'[1]감독 순번'!B6) -> #VALUE! | E6: =COUNTIF([1]감독시간표!$L$11:$S$11,'[1]감독 순번'!B6)+COUNTIF([1]감독시간표!$Y$11:$AE$11,'[1]감독 순번'!B6)+COUNTIF([1]감독시간표!$E$17:$K$17,'[1]감독 순번'!B6)+COUNTIF([1]감독시간표!$T$17:$V$17,'[1]감독 순번'!B6)+COUNTIF([1]감독시간표!$AI$17,'[1]감독 순번'!B6)+COUNTIF([1]감독시간표!$E$20:$S$20,'[1]감독 순번'!B6)+COUNTIF([1]감독시간표!$Y$20:$AE$20,'[1]감독 순번'!B6)+COUNTIF([1]감독시간표!$E$26:$K$26,'[1]감독 순번'!B6)+COUNTIF([1]감독시간표!$T$26:$V$26,'[1]감독 순번'!B6)+COUNTIF([1]감독시간표!$Y$26:$AA$26,'[1]감독 순번'!B6)+COUNTIF([1]감독시간표!$E$29:$S$29,'[1]감독 순번'!B6)+COUNTIF([1]감독시간표!$AA$29:$AC$29,'[1]감독 순번'!B6)+COUNTIF([1]감독시간표!$AF$29:$AI$29,'[1]감독 순번'!B6)+COUNTIF([1]감독시간표!$E$35:$P$35,'[1]감독 순번'!B6)+COUNTIF([1]감독시간표!$AF$35:$AH$35,'[1]감독 순번'!B6)+COUNTIF([1]감독시간표!$E$41:$S$41,'[1]감독 순번'!B6)+COUNTIF([1]감독시간표!$Y$41:$AE$41,'[1]감독 순번'!B6)+COUNTIF([1]감독시간표!$E$47:$Q$47,'[1]감독 순번'!B6)+COUNTIF([1]감독시간표!$Y$47:$AC$47,'[1]감독 순번'!B6) -> #VALUE! | F6: =COUNTIF([1]감독시간표!$E$10:$K$11,'[1]감독 순번'!B6)+COUNTIF([1]감독시간표!$E$13:$S$14,'[1]감독 순번'!B6)+COUNTIF([1]감독시간표!$Y$13:$AE$14,'[1]감독 순번'!B6)+COUNTIF([1]감독시간표!$L$16:$S$17,'[1]감독 순번'!B6)+COUNTIF([1]감독시간표!$Y$16:$AE$17,'[1]감독 순번'!B6)+COUNTIF([1]감독시간표!$E$22:$S$23,'[1]감독 순번'!B6)+COUNTIF([1]감독시간표!$Y$22:$AE$23,'[1]감독 순번'!B6)+COUNTIF([1]감독시간표!$L$25:$S$26,'[1]감독 순번'!B6)+COUNTIF([1]감독시간표!$AJ$25:$AK$26,'[1]감독 순번'!B6)+COUNTIF([1]감독시간표!$E$31:$S$32,'[1]감독 순번'!B6)+COUNTIF([1]감독시간표!$Y$31:$AE$32,'[1]감독 순번'!B6)+COUNTIF([1]감독시간표!$W$34:$AE$35,'[1]감독 순번'!B6)+COUNTIF([1]감독시간표!$E$37:$S$38,'[1]감독 순번'!B6)+COUNTIF([1]감독시간표!$Y$37:$AE$38,'[1]감독 순번'!B6)+COUNTIF([1]감독시간표!$E$43:$S$44,'[1]감독 순번'!B6)+COUNTIF([1]감독시간표!$Y$43:$AE$44,'[1]감독 순번'!B6)+COUNTIF([1]감독시간표!$X$46,'[1]감독 순번'!B6)+COUNTIF([1]감독시간표!$AG$46,'[1]감독 순번'!B6) -> #VALUE! | G6: =SUM(D6:F6) -> #VALUE!
B7: 3 | C7: =[1]감독시간표!E54 -> 이여옥 | D7: =COUNTIF([1]감독시간표!$L$10:$S$10,'[1]감독 순번'!B7)+COUNTIF([1]감독시간표!$Y$10:$AE$10,'[1]감독 순번'!B7)+COUNTIF([1]감독시간표!$E$16:$K$16,'[1]감독 순번'!B7)+COUNTIF([1]감독시간표!$T$16:$V$16,'[1]감독 순번'!B7)+COUNTIF([1]감독시간표!$AI$16,'[1]감독 순번'!B7)+COUNTIF([1]감독시간표!$E$19:$S$19,'[1]감독 순번'!B7)+COUNTIF([1]감독시간표!$Y$19:$AE$19,'[1]감독 순번'!B7)+COUNTIF([1]감독시간표!$E$25:$K$25,'[1]감독 순번'!B7)+COUNTIF([1]감독시간표!$T$25:$V$25,'[1]감독 순번'!B7)+COUNTIF([1]감독시간표!$Y$25:$AA$25,'[1]감독 순번'!B7)+COUNTIF([1]감독시간표!$E$28:$S$28,'[1]감독 순번'!B7)+COUNTIF([1]감독시간표!$AA$28:$AC$28,'[1]감독 순번'!B7)+COUNTIF([1]감독시간표!$AF$28:$AI$28,'[1]감독 순번'!B7)+COUNTIF([1]감독시간표!$E$34:$P$34,'[1]감독 순번'!B7)+COUNTIF([1]감독시간표!$AF$34:$AH$34,'[1]감독 순번'!B7)+COUNTIF([1]감독시간표!$E$40:$S$40,'[1]감독 순번'!B7)+COUNTIF([1]감독시간표!$Y$40:$AE$40,'[1]감독 순번'!B7)+COUNTIF([1]감독시간표!$E$46:$Q$46,'[1]감독 순번'!B7)+COUNTIF([1]감독시간표!$Y$46:$AC$46,'[1]감독 순번'!B7) -> #VALUE! | E7: =COUNTIF([1]감독시간표!$L$11:$S$11,'[1]감독 순번'!B7)+COUNTIF([1]감독시간표!$Y$11:$AE$11,'[1]감독 순번'!B7)+COUNTIF([1]감독시간표!$E$17:$K$17,'[1]감독 순번'!B7)+COUNTIF([1]감독시간표!$T$17:$V$17,'[1]감독 순번'!B7)+COUNTIF([1]감독시간표!$AI$17,'[1]감독 순번'!B7)+COUNTIF([1]감독시간표!$E$20:$S$20,'[1]감독 순번'!B7)+COUNTIF([1]감독시간표!$Y$20:$AE$20,'[1]감독 순번'!B7)+COUNTIF([1]감독시간표!$E$26:$K$26,'[1]감독 순번'!B7)+COUNTIF([1]감독시간표!$T$26:$V$26,'[1]감독 순번'!B7)+COUNTIF([1]감독시간표!$Y$26:$AA$26,'[1]감독 순번'!B7)+COUNTIF([1]감독시간표!$E$29:$S$29,'[1]감독 순번'!B7)+COUNTIF([1]감독시간표!$AA$29:$AC$29,'[1]감독 순번'!B7)+COUNTIF([1]감독시간표!$AF$29:$AI$29,'[1]감독 순번'!B7)+COUNTIF([1]감독시간표!$E$35:$P$35,'[1]감독 순번'!B7)+COUNTIF([1]감독시간표!$AF$35:$AH$35,'[1]감독 순번'!B7)+COUNTIF([1]감독시간표!$E$41:$S$41,'[1]감독 순번'!B7)+COUNTIF([1]감독시간표!$Y$41:$AE$41,'[1]감독 순번'!B7)+COUNTIF([1]감독시간표!$E$47:$Q$47,'[1]감독 순번'!B7)+COUNTIF([1]감독시간표!$Y$47:$AC$47,'[1]감독 순번'!B7) -> #VALUE! | F7: =COUNTIF([1]감독시간표!$E$10:$K$11,'[1]감독 순번'!B7)+COUNTIF([1]감독시간표!$E$13:$S$14,'[1]감독 순번'!B7)+COUNTIF([1]감독시간표!$Y$13:$AE$14,'[1]감독 순번'!B7)+COUNTIF([1]감독시간표!$L$16:$S$17,'[1]감독 순번'!B7)+COUNTIF([1]감독시간표!$Y$16:$AE$17,'[1]감독 순번'!B7)+COUNTIF([1]감독시간표!$E$22:$S$23,'[1]감독 순번'!B7)+COUNTIF([1]감독시간표!$Y$22:$AE$23,'[1]감독 순번'!B7)+COUNTIF([1]감독시간표!$L$25:$S$26,'[1]감독 순번'!B7)+COUNTIF([1]감독시간표!$AJ$25:$AK$26,'[1]감독 순번'!B7)+COUNTIF([1]감독시간표!$E$31:$S$32,'[1]감독 순번'!B7)+COUNTIF([1]감독시간표!$Y$31:$AE$32,'[1]감독 순번'!B7)+COUNTIF([1]감독시간표!$W$34:$AE$35,'[1]감독 순번'!B7)+COUNTIF([1]감독시간표!$E$37:$S$38,'[1]감독 순번'!B7)+COUNTIF([1]감독시간표!$Y$37:$AE$38,'[1]감독 순번'!B7)+COUNTIF([1]감독시간표!$E$43:$S$44,'[1]감독 순번'!B7)+COUNTIF([1]감독시간표!$Y$43:$AE$44,'[1]감독 순번'!B7)+COUNTIF([1]감독시간표!$X$46,'[1]감독 순번'!B7)+COUNTIF([1]감독시간표!$AG$46,'[1]감독 순번'!B7) -> #VALUE! | G7: =SUM(D7:F7) -> #VALUE!
B8: 4 | C8: =[1]감독시간표!E55 -> 류길수 | D8: =COUNTIF([1]감독시간표!$L$10:$S$10,'[1]감독 순번'!B8)+COUNTIF([1]감독시간표!$Y$10:$AE$10,'[1]감독 순번'!B8)+COUNTIF([1]감독시간표!$E$16:$K$16,'[1]감독 순번'!B8)+COUNTIF([1]감독시간표!$T$16:$V$16,'[1]감독 순번'!B8)+COUNTIF([1]감독시간표!$AI$16,'[1]감독 순번'!B8)+COUNTIF([1]감독시간표!$E$19:$S$19,'[1]감독 순번'!B8)+COUNTIF([1]감독시간표!$Y$19:$AE$19,'[1]감독 순번'!B8)+COUNTIF([1]감독시간표!$E$25:$K$25,'[1]감독 순번'!B8)+COUNTIF([1]감독시간표!$T$25:$V$25,'[1]감독 순번'!B8)+COUNTIF([1]감독시간표!$Y$25:$AA$25,'[1]감독 순번'!B8)+COUNTIF([1]감독시간표!$E$28:$S$28,'[1]감독 순번'!B8)+COUNTIF([1]감독시간표!$AA$28:$AC$28,'[1]감독 순번'!B8)+COUNTIF([1]감독시간표!$AF$28:$AI$28,'[1]감독 순번'!B8)+COUNTIF([1]감독시간표!$E$34:$P$34,'[1]감독 순번'!B8)+COUNTIF([1]감독시간표!$AF$34:$AH$34,'[1]감독 순번'!B8)+COUNTIF([1]감독시간표!$E$40:$S$40,'[1]감독 순번'!B8)+COUNTIF([1]감독시간표!$Y$40:$AE$40,'[1]감독 순번'!B8)+COUNTIF([1]감독시간표!$E$46:$Q$46,'[1]감독 순번'!B8)+COUNTIF([1]감독시간표!$Y$46:$AC$46,'[1]감독 순번'!B8) -> #VALUE! | E8: =COUNTIF([1]감독시간표!$L$11:$S$11,'[1]감독 순번'!B8)+COUNTIF([1]감독시간표!$Y$11:$AE$11,'[1]감독 순번'!B8)+COUNTIF([1]감독시간표!$E$17:$K$17,'[1]감독 순번'!B8)+COUNTIF([1]감독시간표!$T$17:$V$17,'[1]감독 순번'!B8)+COUNTIF([1]감독시간표!$AI$17,'[1]감독 순번'!B8)+COUNTIF([1]감독시간표!$E$20:$S$20,'[1]감독 순번'!B8)+COUNTIF([1]감독시간표!$Y$20:$AE$20,'[1]감독 순번'!B8)+COUNTIF([1]감독시간표!$E$26:$K$26,'[1]감독 순번'!B8)+COUNTIF([1]감독시간표!$T$26:$V$26,'[1]감독 순번'!B8)+COUNTIF([1]감독시간표!$Y$26:$AA$26,'[1]감독 순번'!B8)+COUNTIF([1]감독시간표!$E$29:$S$29,'[1]감독 순번'!B8)+COUNTIF([1]감독시간표!$AA$29:$AC$29,'[1]감독 순번'!B8)+COUNTIF([1]감독시간표!$AF$29:$AI$29,'[1]감독 순번'!B8)+COUNTIF([1]감독시간표!$E$35:$P$35,'[1]감독 순번'!B8)+COUNTIF([1]감독시간표!$AF$35:$AH$35,'[1]감독 순번'!B8)+COUNTIF([1]감독시간표!$E$41:$S$41,'[1]감독 순번'!B8)+COUNTIF([1]감독시간표!$Y$41:$AE$41,'[1]감독 순번'!B8)+COUNTIF([1]감독시간표!$E$47:$Q$47,'[1]감독 순번'!B8)+COUNTIF([1]감독시간표!$Y$47:$AC$47,'[1]감독 순번'!B8) -> #VALUE! | F8: =COUNTIF([1]감독시간표!$E$10:$K$11,'[1]감독 순번'!B8)+COUNTIF([1]감독시간표!$E$13:$S$14,'[1]감독 순번'!B8)+COUNTIF([1]감독시간표!$Y$13:$AE$14,'[1]감독 순번'!B8)+COUNTIF([1]감독시간표!$L$16:$S$17,'[1]감독 순번'!B8)+COUNTIF([1]감독시간표!$Y$16:$AE$17,'[1]감독 순번'!B8)+COUNTIF([1]감독시간표!$E$22:$S$23,'[1]감독 순번'!B8)+COUNTIF([1]감독시간표!$Y$22:$AE$23,'[1]감독 순번'!B8)+COUNTIF([1]감독시간표!$L$25:$S$26,'[1]감독 순번'!B8)+COUNTIF([1]감독시간표!$AJ$25:$AK$26,'[1]감독 순번'!B8)+COUNTIF([1]감독시간표!$E$31:$S$32,'[1]감독 순번'!B8)+COUNTIF([1]감독시간표!$Y$31:$AE$32,'[1]감독 순번'!B8)+COUNTIF([1]감독시간표!$W$34:$AE$35,'[1]감독 순번'!B8)+COUNTIF([1]감독시간표!$E$37:$S$38,'[1]감독 순번'!B8)+COUNTIF([1]감독시간표!$Y$37:$AE$38,'[1]감독 순번'!B8)+COUNTIF([1]감독시간표!$E$43:$S$44,'[1]감독 순번'!B8)+COUNTIF([1]감독시간표!$Y$43:$AE$44,'[1]감독 순번'!B8)+COUNTIF([1]감독시간표!$X$46,'[1]감독 순번'!B8)+COUNTIF([1]감독시간표!$AG$46,'[1]감독 순번'!B8) -> #VALUE! | G8: =SUM(D8:F8) -> #VALUE! | Q8: 생활과윤리
B9: 5 | C9: =[1]감독시간표!E56 -> 박진성 | D9: =COUNTIF([1]감독시간표!$L$10:$S$10,'[1]감독 순번'!B9)+COUNTIF([1]감독시간표!$Y$10:$AE$10,'[1]감독 순번'!B9)+COUNTIF([1]감독시간표!$E$16:$K$16,'[1]감독 순번'!B9)+COUNTIF([1]감독시간표!$T$16:$V$16,'[1]감독 순번'!B9)+COUNTIF([1]감독시간표!$AI$16,'[1]감독 순번'!B9)+COUNTIF([1]감독시간표!$E$19:$S$19,'[1]감독 순번'!B9)+COUNTIF([1]감독시간표!$Y$19:$AE$19,'[1]감독 순번'!B9)+COUNTIF([1]감독시간표!$E$25:$K$25,'[1]감독 순번'!B9)+COUNTIF([1]감독시간표!$T$25:$V$25,'[1]감독 순번'!B9)+COUNTIF([1]감독시간표!$Y$25:$AA$25,'[1]감독 순번'!B9)+COUNTIF([1]감독시간표!$E$28:$S$28,'[1]감독 순번'!B9)+COUNTIF([1]감독시간표!$AA$28:$AC$28,'[1]감독 순번'!B9)+COUNTIF([1]감독시간표!$AF$28:$AI$28,'[1]감독 순번'!B9)+COUNTIF([1]감독시간표!$E$34:$P$34,'[1]감독 순번'!B9)+COUNTIF([1]감독시간표!$AF$34:$AH$34,'[1]감독 순번'!B9)+COUNTIF([1]감독시간표!$E$40:$S$40,'[1]감독 순번'!B9)+COUNTIF([1]감독시간표!$Y$40:$AE$40,'[1]감독 순번'!B9)+COUNTIF([1]감독시간표!$E$46:$Q$46,'[1]감독 순번'!B9)+COUNTIF([1]감독시간표!$Y$46:$AC$46,'[1]감독 순번'!B9) -> #VALUE! | E9: =COUNTIF([1]감독시간표!$L$11:$S$11,'[1]감독 순번'!B9)+COUNTIF([1]감독시간표!$Y$11:$AE$11,'[1]감독 순번'!B9)+COUNTIF([1]감독시간표!$E$17:$K$17,'[1]감독 순번'!B9)+COUNTIF([1]감독시간표!$T$17:$V$17,'[1]감독 순번'!B9)+COUNTIF([1]감독시간표!$AI$17,'[1]감독 순번'!B9)+COUNTIF([1]감독시간표!$E$20:$S$20,'[1]감독 순번'!B9)+COUNTIF([1]감독시간표!$Y$20:$AE$20,'[1]감독 순번'!B9)+COUNTIF([1]감독시간표!$E$26:$K$26,'[1]감독 순번'!B9)+COUNTIF([1]감독시간표!$T$26:$V$26,'[1]감독 순번'!B9)+COUNTIF([1]감독시간표!$Y$26:$AA$26,'[1]감독 순번'!B9)+COUNTIF([1]감독시간표!$E$29:$S$29,'[1]감독 순번'!B9)+COUNTIF([1]감독시간표!$AA$29:$AC$29,'[1]감독 순번'!B9)+COUNTIF([1]감독시간표!$AF$29:$AI$29,'[1]감독 순번'!B9)+COUNTIF([1]감독시간표!$E$35:$P$35,'[1]감독 순번'!B9)+COUNTIF([1]감독시간표!$AF$35:$AH$35,'[1]감독 순번'!B9)+COUNTIF([1]감독시간표!$E$41:$S$41,'[1]감독 순번'!B9)+COUNTIF([1]감독시간표!$Y$41:$AE$41,'[1]감독 순번'!B9)+COUNTIF([1]감독시간표!$E$47:$Q$47,'[1]감독 순번'!B9)+COUNTIF([1]감독시간표!$Y$47:$AC$47,'[1]감독 순번'!B9) -> #VALUE! | F9: =COUNTIF([1]감독시간표!$E$10:$K$11,'[1]감독 순번'!B9)+COUNTIF([1]감독시간표!$E$13:$S$14,'[1]감독 순번'!B9)+COUNTIF([1]감독시간표!$Y$13:$AE$14,'[1]감독 순번'!B9)+COUNTIF([1]감독시간표!$L$16:$S$17,'[1]감독 순번'!B9)+COUNTIF([1]감독시간표!$Y$16:$AE$17,'[1]감독 순번'!B9)+COUNTIF([1]감독시간표!$E$22:$S$23,'[1]감독 순번'!B9)+COUNTIF([1]감독시간표!$Y$22:$AE$23,'[1]감독 순번'!B9)+COUNTIF([1]감독시간표!$L$25:$S$26,'[1]감독 순번'!B9)+COUNTIF([1]감독시간표!$AJ$25:$AK$26,'[1]감독 순번'!B9)+COUNTIF([1]감독시간표!$E$31:$S$32,'[1]감독 순번'!B9)+COUNTIF([1]감독시간표!$Y$31:$AE$32,'[1]감독 순번'!B9)+COUNTIF([1]감독시간표!$W$34:$AE$35,'[1]감독 순번'!B9)+COUNTIF([1]감독시간표!$E$37:$S$38,'[1]감독 순번'!B9)+COUNTIF([1]감독시간표!$Y$37:$AE$38,'[1]감독 순번'!B9)+COUNTIF([1]감독시간표!$E$43:$S$44,'[1]감독 순번'!B9)+COUNTIF([1]감독시간표!$Y$43:$AE$44,'[1]감독 순번'!B9)+COUNTIF([1]감독시간표!$X$46,'[1]감독 순번'!B9)+COUNTIF([1]감독시간표!$AG$46,'[1]감독 순번'!B9) -> #VALUE! | G9: =SUM(D9:F9) -> #VALUE!
B10: 6 | C10: =[1]감독시간표!E57 -> 최병선 | D10: =COUNTIF([1]감독시간표!$L$10:$S$10,'[1]감독 순번'!B10)+COUNTIF([1]감독시간표!$Y$10:$AE$10,'[1]감독 순번'!B10)+COUNTIF([1]감독시간표!$E$16:$K$16,'[1]감독 순번'!B10)+COUNTIF([1]감독시간표!$T$16:$V$16,'[1]감독 순번'!B10)+COUNTIF([1]감독시간표!$AI$16,'[1]감독 순번'!B10)+COUNTIF([1]감독시간표!$E$19:$S$19,'[1]감독 순번'!B10)+COUNTIF([1]감독시간표!$Y$19:$AE$19,'[1]감독 순번'!B10)+COUNTIF([1]감독시간표!$E$25:$K$25,'[1]감독 순번'!B10)+COUNTIF([1]감독시간표!$T$25:$V$25,'[1]감독 순번'!B10)+COUNTIF([1]감독시간표!$Y$25:$AA$25,'[1]감독 순번'!B10)+COUNTIF([1]감독시간표!$E$28:$S$28,'[1]감독 순번'!B10)+COUNTIF([1]감독시간표!$AA$28:$AC$28,'[1]감독 순번'!B10)+COUNTIF([1]감독시간표!$AF$28:$AI$28,'[1]감독 순번'!B10)+COUNTIF([1]감독시간표!$E$34:$P$34,'[1]감독 순번'!B10)+COUNTIF([1]감독시간표!$AF$34:$AH$34,'[1]감독 순번'!B10)+COUNTIF([1]감독시간표!$E$40:$S$40,'[1]감독 순번'!B10)+COUNTIF([1]감독시간표!$Y$40:$AE$40,'[1]감독 순번'!B10)+COUNTIF([1]감독시간표!$E$46:$Q$46,'[1]감독 순번'!B10)+COUNTIF([1]감독시간표!$Y$46:$AC$46,'[1]감독 순번'!B10) -> #VALUE! | E10: =COUNTIF([1]감독시간표!$L$11:$S$11,'[1]감독 순번'!B10)+COUNTIF([1]감독시간표!$Y$11:$AE$11,'[1]감독 순번'!B10)+COUNTIF([1]감독시간표!$E$17:$K$17,'[1]감독 순번'!B10)+COUNTIF([1]감독시간표!$T$17:$V$17,'[1]감독 순번'!B10)+COUNTIF([1]감독시간표!$AI$17,'[1]감독 순번'!B10)+COUNTIF([1]감독시간표!$E$20:$S$20,'[1]감독 순번'!B10)+COUNTIF([1]감독시간표!$Y$20:$AE$20,'[1]감독 순번'!B10)+COUNTIF([1]감독시간표!$E$26:$K$26,'[1]감독 순번'!B10)+COUNTIF([1]감독시간표!$T$26:$V$26,'[1]감독 순번'!B10)+COUNTIF([1]감독시간표!$Y$26:$AA$26,'[1]감독 순번'!B10)+COUNTIF([1]감독시간표!$E$29:$S$29,'[1]감독 순번'!B10)+COUNTIF([1]감독시간표!$AA$29:$AC$29,'[1]감독 순번'!B10)+COUNTIF([1]감독시간표!$AF$29:$AI$29,'[1]감독 순번'!B10)+COUNTIF([1]감독시간표!$E$35:$P$35,'[1]감독 순번'!B10)+COUNTIF([1]감독시간표!$AF$35:$AH$35,'[1]감독 순번'!B10)+COUNTIF([1]감독시간표!$E$41:$S$41,'[1]감독 순번'!B10)+COUNTIF([1]감독시간표!$Y$41:$AE$41,'[1]감독 순번'!B10)+COUNTIF([1]감독시간표!$E$47:$Q$47,'[1]감독 순번'!B10)+COUNTIF([1]감독시간표!$Y$47:$AC$47,'[1]감독 순번'!B10) -> #VALUE! | F10: =COUNTIF([1]감독시간표!$E$10:$K$11,'[1]감독 순번'!B10)+COUNTIF([1]감독시간표!$E$13:$S$14,'[1]감독 순번'!B10)+COUNTIF([1]감독시간표!$Y$13:$AE$14,'[1]감독 순번'!B10)+COUNTIF([1]감독시간표!$L$16:$S$17,'[1]감독 순번'!B10)+COUNTIF([1]감독시간표!$Y$16:$AE$17,'[1]감독 순번'!B10)+COUNTIF([1]감독시간표!$E$22:$S$23,'[1]감독 순번'!B10)+COUNTIF([1]감독시간표!$Y$22:$AE$23,'[1]감독 순번'!B10)+COUNTIF([1]감독시간표!$L$25:$S$26,'[1]감독 순번'!B10)+COUNTIF([1]감독시간표!$AJ$25:$AK$26,'[1]감독 순번'!B10)+COUNTIF([1]감독시간표!$E$31:$S$32,'[1]감독 순번'!B10)+COUNTIF([1]감독시간표!$Y$31:$AE$32,'[1]감독 순번'!B10)+COUNTIF([1]감독시간표!$W$34:$AE$35,'[1]감독 순번'!B10)+COUNTIF([1]감독시간표!$E$37:$S$38,'[1]감독 순번'!B10)+COUNTIF([1]감독시간표!$Y$37:$AE$38,'[1]감독 순번'!B10)+COUNTIF([1]감독시간표!$E$43:$S$44,'[1]감독 순번'!B10)+COUNTIF([1]감독시간표!$Y$43:$AE$44,'[1]감독 순번'!B10)+COUNTIF([1]감독시간표!$X$46,'[1]감독 순번'!B10)+COUNTIF([1]감독시간표!$AG$46,'[1]감독 순번'!B10) -> #VALUE! | G10: =SUM(D10:F10) -> #VALUE!
B11: 7 | C11: =[1]감독시간표!E58 -> 유미 | D11: =COUNTIF([1]감독시간표!$L$10:$S$10,'[1]감독 순번'!B11)+COUNTIF([1]감독시간표!$Y$10:$AE$10,'[1]감독 순번'!B11)+COUNTIF([1]감독시간표!$E$16:$K$16,'[1]감독 순번'!B11)+COUNTIF([1]감독시간표!$T$16:$V$16,'[1]감독 순번'!B11)+COUNTIF([1]감독시간표!$AI$16,'[1]감독 순번'!B11)+COUNTIF([1]감독시간표!$E$19:$S$19,'[1]감독 순번'!B11)+COUNTIF([1]감독시간표!$Y$19:$AE$19,'[1]감독 순번'!B11)+COUNTIF([1]감독시간표!$E$25:$K$25,'[1]감독 순번'!B11)+COUNTIF([1]감독시간표!$T$25:$V$25,'[1]감독 순번'!B11)+COUNTIF([1]감독시간표!$Y$25:$AA$25,'[1]감독 순번'!B11)+COUNTIF([1]감독시간표!$E$28:$S$28,'[1]감독 순번'!B11)+COUNTIF([1]감독시간표!$AA$28:$AC$28,'[1]감독 순번'!B11)+COUNTIF([1]감독시간표!$AF$28:$AI$28,'[1]감독 순번'!B11)+COUNTIF([1]감독시간표!$E$34:$P$34,'[1]감독 순번'!B11)+COUNTIF([1]감독시간표!$AF$34:$AH$34,'[1]감독 순번'!B11)+COUNTIF([1]감독시간표!$E$40:$S$40,'[1]감독 순번'!B11)+COUNTIF([1]감독시간표!$Y$40:$AE$40,'[1]감독 순번'!B11)+COUNTIF([1]감독시간표!$E$46:$Q$46,'[1]감독 순번'!B11)+COUNTIF([1]감독시간표!$Y$46:$AC$46,'[1]감독 순번'!B11) -> #VALUE! | E11: =COUNTIF([1]감독시간표!$L$11:$S$11,'[1]감독 순번'!B11)+COUNTIF([1]감독시간표!$Y$11:$AE$11,'[1]감독 순번'!B11)+COUNTIF([1]감독시간표!$E$17:$K$17,'[1]감독 순번'!B11)+COUNTIF([1]감독시간표!$T$17:$V$17,'[1]감독 순번'!B11)+COUNTIF([1]감독시간표!$AI$17,'[1]감독 순번'!B11)+COUNTIF([1]감독시간표!$E$20:$S$20,'[1]감독 순번'!B11)+COUNTIF([1]감독시간표!$Y$20:$AE$20,'[1]감독 순번'!B11)+COUNTIF([1]감독시간표!$E$26:$K$26,'[1]감독 순번'!B11)+COUNTIF([1]감독시간표!$T$26:$V$26,'[1]감독 순번'!B11)+COUNTIF([1]감독시간표!$Y$26:$AA$26,'[1]감독 순번'!B11)+COUNTIF([1]감독시간표!$E$29:$S$29,'[1]감독 순번'!B11)+COUNTIF([1]감독시간표!$AA$29:$AC$29,'[1]감독 순번'!B11)+COUNTIF([1]감독시간표!$AF$29:$AI$29,'[1]감독 순번'!B11)+COUNTIF([1]감독시간표!$E$35:$P$35,'[1]감독 순번'!B11)+COUNTIF([1]감독시간표!$AF$35:$AH$35,'[1]감독 순번'!B11)+COUNTIF([1]감독시간표!$E$41:$S$41,'[1]감독 순번'!B11)+COUNTIF([1]감독시간표!$Y$41:$AE$41,'[1]감독 순번'!B11)+COUNTIF([1]감독시간표!$E$47:$Q$47,'[1]감독 순번'!B11)+COUNTIF([1]감독시간표!$Y$47:$AC$47,'[1]감독 순번'!B11) -> #VALUE! | F11: =COUNTIF([1]감독시간표!$E$10:$K$11,'[1]감독 순번'!B11)+COUNTIF([1]감독시간표!$E$13:$S$14,'[1]감독 순번'!B11)+COUNTIF([1]감독시간표!$Y$13:$AE$14,'[1]감독 순번'!B11)+COUNTIF([1]감독시간표!$L$16:$S$17,'[1]감독 순번'!B11)+COUNTIF([1]감독시간표!$Y$16:$AE$17,'[1]감독 순번'!B11)+COUNTIF([1]감독시간표!$E$22:$S$23,'[1]감독 순번'!B11)+COUNTIF([1]감독시간표!$Y$22:$AE$23,'[1]감독 순번'!B11)+COUNTIF([1]감독시간표!$L$25:$S$26,'[1]감독 순번'!B11)+COUNTIF([1]감독시간표!$AJ$25:$AK$26,'[1]감독 순번'!B11)+COUNTIF([1]감독시간표!$E$31:$S$32,'[1]감독 순번'!B11)+COUNTIF([1]감독시간표!$Y$31:$AE$32,'[1]감독 순번'!B11)+COUNTIF([1]감독시간표!$W$34:$AE$35,'[1]감독 순번'!B11)+COUNTIF([1]감독시간표!$E$37:$S$38,'[1]감독 순번'!B11)+COUNTIF([1]감독시간표!$Y$37:$AE$38,'[1]감독 순번'!B11)+COUNTIF([1]감독시간표!$E$43:$S$44,'[1]감독 순번'!B11)+COUNTIF([1]감독시간표!$Y$43:$AE$44,'[1]감독 순번'!B11)+COUNTIF([1]감독시간표!$X$46,'[1]감독 순번'!B11)+COUNTIF([1]감독시간표!$AG$46,'[1]감독 순번'!B11) -> #VALUE! | G11: =SUM(D11:F11) -> #VALUE!
B12: 8 | C12: =[1]감독시간표!E59 -> 양향숙 | D12: =COUNTIF([1]감독시간표!$L$10:$S$10,'[1]감독 순번'!B12)+COUNTIF([1]감독시간표!$Y$10:$AE$10,'[1]감독 순번'!B12)+COUNTIF([1]감독시간표!$E$16:$K$16,'[1]감독 순번'!B12)+COUNTIF([1]감독시간표!$T$16:$V$16,'[1]감독 순번'!B12)+COUNTIF([1]감독시간표!$AI$16,'[1]감독 순번'!B12)+COUNTIF([1]감독시간표!$E$19:$S$19,'[1]감독 순번'!B12)+COUNTIF([1]감독시간표!$Y$19:$AE$19,'[1]감독 순번'!B12)+COUNTIF([1]감독시간표!$E$25:$K$25,'[1]감독 순번'!B12)+COUNTIF([1]감독시간표!$T$25:$V$25,'[1]감독 순번'!B12)+COUNTIF([1]감독시간표!$Y$25:$AA$25,'[1]감독 순번'!B12)+COUNTIF([1]감독시간표!$E$28:$S$28,'[1]감독 순번'!B12)+COUNTIF([1]감독시간표!$AA$28:$AC$28,'[1]감독 순번'!B12)+COUNTIF([1]감독시간표!$AF$28:$AI$28,'[1]감독 순번'!B12)+COUNTIF([1]감독시간표!$E$34:$P$34,'[1]감독 순번'!B12)+COUNTIF([1]감독시간표!$AF$34:$AH$34,'[1]감독 순번'!B12)+COUNTIF([1]감독시간표!$E$40:$S$40,'[1]감독 순번'!B12)+COUNTIF([1]감독시간표!$Y$40:$AE$40,'[1]감독 순번'!B12)+COUNTIF([1]감독시간표!$E$46:$Q$46,'[1]감독 순번'!B12)+COUNTIF([1]감독시간표!$Y$46:$AC$46,'[1]감독 순번'!B12) -> #VALUE! | E12: =COUNTIF([1]감독시간표!$L$11:$S$11,'[1]감독 순번'!B12)+COUNTIF([1]감독시간표!$Y$11:$AE$11,'[1]감독 순번'!B12)+COUNTIF([1]감독시간표!$E$17:$K$17,'[1]감독 순번'!B12)+COUNTIF([1]감독시간표!$T$17:$V$17,'[1]감독 순번'!B12)+COUNTIF([1]감독시간표!$AI$17,'[1]감독 순번'!B12)+COUNTIF([1]감독시간표!$E$20:$S$20,'[1]감독 순번'!B12)+COUNTIF([1]감독시간표!$Y$20:$AE$20,'[1]감독 순번'!B12)+COUNTIF([1]감독시간표!$E$26:$K$26,'[1]감독 순번'!B12)+COUNTIF([1]감독시간표!$T$26:$V$26,'[1]감독 순번'!B12)+COUNTIF([1]감독시간표!$Y$26:$AA$26,'[1]감독 순번'!B12)+COUNTIF([1]감독시간표!$E$29:$S$29,'[1]감독 순번'!B12)+COUNTIF([1]감독시간표!$AA$29:$AC$29,'[1]감독 순번'!B12)+COUNTIF([1]감독시간표!$AF$29:$AI$29,'[1]감독 순번'!B12)+COUNTIF([1]감독시간표!$E$35:$P$35,'[1]감독 순번'!B12)+COUNTIF([1]감독시간표!$AF$35:$AH$35,'[1]감독 순번'!B12)+COUNTIF([1]감독시간표!$E$41:$S$41,'[1]감독 순번'!B12)+COUNTIF([1]감독시간표!$Y$41:$AE$41,'[1]감독 순번'!B12)+COUNTIF([1]감독시간표!$E$47:$Q$47,'[1]감독 순번'!B12)+COUNTIF([1]감독시간표!$Y$47:$AC$47,'[1]감독 순번'!B12) -> #VALUE! | F12: =COUNTIF([1]감독시간표!$E$10:$K$11,'[1]감독 순번'!B12)+COUNTIF([1]감독시간표!$E$13:$S$14,'[1]감독 순번'!B12)+COUNTIF([1]감독시간표!$Y$13:$AE$14,'[1]감독 순번'!B12)+COUNTIF([1]감독시간표!$L$16:$S$17,'[1]감독 순번'!B12)+COUNTIF([1]감독시간표!$Y$16:$AE$17,'[1]감독 순번'!B12)+COUNTIF([1]감독시간표!$E$22:$S$23,'[1]감독 순번'!B12)+COUNTIF([1]감독시간표!$Y$22:$AE$23,'[1]감독 순번'!B12)+COUNTIF([1]감독시간표!$L$25:$S$26,'[1]감독 순번'!B12)+COUNTIF([1]감독시간표!$AJ$25:$AK$26,'[1]감독 순번'!B12)+COUNTIF([1]감독시간표!$E$31:$S$32,'[1]감독 순번'!B12)+COUNTIF([1]감독시간표!$Y$31:$AE$32,'[1]감독 순번'!B12)+COUNTIF([1]감독시간표!$W$34:$AE$35,'[1]감독 순번'!B12)+COUNTIF([1]감독시간표!$E$37:$S$38,'[1]감독 순번'!B12)+COUNTIF([1]감독시간표!$Y$37:$AE$38,'[1]감독 순번'!B12)+COUNTIF([1]감독시간표!$E$43:$S$44,'[1]감독 순번'!B12)+COUNTIF([1]감독시간표!$Y$43:$AE$44,'[1]감독 순번'!B12)+COUNTIF([1]감독시간표!$X$46,'[1]감독 순번'!B12)+COUNTIF([1]감독시간표!$AG$46,'[1]감독 순번'!B12) -> #VALUE! | G12: =SUM(D12:F12) -> #VALUE!
B13: 9 | C13: =[1]감독시간표!E60 -> 차용매 | D13: =COUNTIF([1]감독시간표!$L$10:$S$10,'[1]감독 순번'!B13)+COUNTIF([1]감독시간표!$Y$10:$AE$10,'[1]감독 순번'!B13)+COUNTIF([1]감독시간표!$E$16:$K$16,'[1]감독 순번'!B13)+COUNTIF([1]감독시간표!$T$16:$V$16,'[1]감독 순번'!B13)+COUNTIF([1]감독시간표!$AI$16,'[1]감독 순번'!B13)+COUNTIF([1]감독시간표!$E$19:$S$19,'[1]감독 순번'!B13)+COUNTIF([1]감독시간표!$Y$19:$AE$19,'[1]감독 순번'!B13)+COUNTIF([1]감독시간표!$E$25:$K$25,'[1]감독 순번'!B13)+COUNTIF([1]감독시간표!$T$25:$V$25,'[1]감독 순번'!B13)+COUNTIF([1]감독시간표!$Y$25:$AA$25,'[1]감독 순번'!B13)+COUNTIF([1]감독시간표!$E$28:$S$28,'[1]감독 순번'!B13)+COUNTIF([1]감독시간표!$AA$28:$AC$28,'[1]감독 순번'!B13)+COUNTIF([1]감독시간표!$AF$28:$AI$28,'[1]감독 순번'!B13)+COUNTIF([1]감독시간표!$E$34:$P$34,'[1]감독 순번'!B13)+COUNTIF([1]감독시간표!$AF$34:$AH$34,'[1]감독 순번'!B13)+COUNTIF([1]감독시간표!$E$40:$S$40,'[1]감독 순번'!B13)+COUNTIF([1]감독시간표!$Y$40:$AE$40,'[1]감독 순번'!B13)+COUNTIF([1]감독시간표!$E$46:$Q$46,'[1]감독 순번'!B13)+COUNTIF([1]감독시간표!$Y$46:$AC$46,'[1]감독 순번'!B13) -> #VALUE! | E13: =COUNTIF([1]감독시간표!$L$11:$S$11,'[1]감독 순번'!B13)+COUNTIF([1]감독시간표!$Y$11:$AE$11,'[1]감독 순번'!B13)+COUNTIF([1]감독시간표!$E$17:$K$17,'[1]감독 순번'!B13)+COUNTIF([1]감독시간표!$T$17:$V$17,'[1]감독 순번'!B13)+COUNTIF([1]감독시간표!$AI$17,'[1]감독 순번'!B13)+COUNTIF([1]감독시간표!$E$20:$S$20,'[1]감독 순번'!B13)+COUNTIF([1]감독시간표!$Y$20:$AE$20,'[1]감독 순번'!B13)+COUNTIF([1]감독시간표!$E$26:$K$26,'[1]감독 순번'!B13)+COUNTIF([1]감독시간표!$T$26:$V$26,'[1]감독 순번'!B13)+COUNTIF([1]감독시간표!$Y$26:$AA$26,'[1]감독 순번'!B13)+COUNTIF([1]감독시간표!$E$29:$S$29,'[1]감독 순번'!B13)+COUNTIF([1]감독시간표!$AA$29:$AC$29,'[1]감독 순번'!B13)+COUNTIF([1]감독시간표!$AF$29:$AI$29,'[1]감독 순번'!B13)+COUNTIF([1]감독시간표!$E$35:$P$35,'[1]감독 순번'!B13)+COUNTIF([1]감독시간표!$AF$35:$AH$35,'[1]감독 순번'!B13)+COUNTIF([1]감독시간표!$E$41:$S$41,'[1]감독 순번'!B13)+COUNTIF([1]감독시간표!$Y$41:$AE$41,'[1]감독 순번'!B13)+COUNTIF([1]감독시간표!$E$47:$Q$47,'[1]감독 순번'!B13)+COUNTIF([1]감독시간표!$Y$47:$AC$47,'[1]감독 순번'!B13) -> #VALUE! | F13: =COUNTIF([1]감독시간표!$E$10:$K$11,'[1]감독 순번'!B13)+COUNTIF([1]감독시간표!$E$13:$S$14,'[1]감독 순번'!B13)+COUNTIF([1]감독시간표!$Y$13:$AE$14,'[1]감독 순번'!B13)+COUNTIF([1]감독시간표!$L$16:$S$17,'[1]감독 순번'!B13)+COUNTIF([1]감독시간표!$Y$16:$AE$17,'[1]감독 순번'!B13)+COUNTIF([1]감독시간표!$E$22:$S$23,'[1]감독 순번'!B13)+COUNTIF([1]감독시간표!$Y$22:$AE$23,'[1]감독 순번'!B13)+COUNTIF([1]감독시간표!$L$25:$S$26,'[1]감독 순번'!B13)+COUNTIF([1]감독시간표!$AJ$25:$AK$26,'[1]감독 순번'!B13)+COUNTIF([1]감독시간표!$E$31:$S$32,'[1]감독 순번'!B13)+COUNTIF([1]감독시간표!$Y$31:$AE$32,'[1]감독 순번'!B13)+COUNTIF([1]감독시간표!$W$34:$AE$35,'[1]감독 순번'!B13)+COUNTIF([1]감독시간표!$E$37:$S$38,'[1]감독 순번'!B13)+COUNTIF([1]감독시간표!$Y$37:$AE$38,'[1]감독 순번'!B13)+COUNTIF([1]감독시간표!$E$43:$S$44,'[1]감독 순번'!B13)+COUNTIF([1]감독시간표!$Y$43:$AE$44,'[1]감독 순번'!B13)+COUNTIF([1]감독시간표!$X$46,'[1]감독 순번'!B13)+COUNTIF([1]감독시간표!$AG$46,'[1]감독 순번'!B13) -> #VALUE! | G13: =SUM(D13:F13) -> #VALUE!
B14: 10 | C14: =[1]감독시간표!E61 -> 김남희 | D14: =COUNTIF([1]감독시간표!$L$10:$S$10,'[1]감독 순번'!B14)+COUNTIF([1]감독시간표!$Y$10:$AE$10,'[1]감독 순번'!B14)+COUNTIF([1]감독시간표!$E$16:$K$16,'[1]감독 순번'!B14)+COUNTIF([1]감독시간표!$T$16:$V$16,'[1]감독 순번'!B14)+COUNTIF([1]감독시간표!$AI$16,'[1]감독 순번'!B14)+COUNTIF([1]감독시간표!$E$19:$S$19,'[1]감독 순번'!B14)+COUNTIF([1]감독시간표!$Y$19:$AE$19,'[1]감독 순번'!B14)+COUNTIF([1]감독시간표!$E$25:$K$25,'[1]감독 순번'!B14)+COUNTIF([1]감독시간표!$T$25:$V$25,'[1]감독 순번'!B14)+COUNTIF([1]감독시간표!$Y$25:$AA$25,'[1]감독 순번'!B14)+COUNTIF([1]감독시간표!$E$28:$S$28,'[1]감독 순번'!B14)+COUNTIF([1]감독시간표!$AA$28:$AC$28,'[1]감독 순번'!B14)+COUNTIF([1]감독시간표!$AF$28:$AI$28,'[1]감독 순번'!B14)+COUNTIF([1]감독시간표!$E$34:$P$34,'[1]감독 순번'!B14)+COUNTIF([1]감독시간표!$AF$34:$AH$34,'[1]감독 순번'!B14)+COUNTIF([1]감독시간표!$E$40:$S$40,'[1]감독 순번'!B14)+COUNTIF([1]감독시간표!$Y$40:$AE$40,'[1]감독 순번'!B14)+COUNTIF([1]감독시간표!$E$46:$Q$46,'[1]감독 순번'!B14)+COUNTIF([1]감독시간표!$Y$46:$AC$46,'[1]감독 순번'!B14) -> #VALUE! | E14: =COUNTIF([1]감독시간표!$L$11:$S$11,'[1]감독 순번'!B14)+COUNTIF([1]감독시간표!$Y$11:$AE$11,'[1]감독 순번'!B14)+COUNTIF([1]감독시간표!$E$17:$K$17,'[1]감독 순번'!B14)+COUNTIF([1]감독시간표!$T$17:$V$17,'[1]감독 순번'!B14)+COUNTIF([1]감독시간표!$AI$17,'[1]감독 순번'!B14)+COUNTIF([1]감독시간표!$E$20:$S$20,'[1]감독 순번'!B14)+COUNTIF([1]감독시간표!$Y$20:$AE$20,'[1]감독 순번'!B14)+COUNTIF([1]감독시간표!$E$26:$K$26,'[1]감독 순번'!B14)+COUNTIF([1]감독시간표!$T$26:$V$26,'[1]감독 순번'!B14)+COUNTIF([1]감독시간표!$Y$26:$AA$26,'[1]감독 순번'!B14)+COUNTIF([1]감독시간표!$E$29:$S$29,'[1]감독 순번'!B14)+COUNTIF([1]감독시간표!$AA$29:$AC$29,'[1]감독 순번'!B14)+COUNTIF([1]감독시간표!$AF$29:$AI$29,'[1]감독 순번'!B14)+COUNTIF([1]감독시간표!$E$35:$P$35,'[1]감독 순번'!B14)+COUNTIF([1]감독시간표!$AF$35:$AH$35,'[1]감독 순번'!B14)+COUNTIF([1]감독시간표!$E$41:$S$41,'[1]감독 순번'!B14)+COUNTIF([1]감독시간표!$Y$41:$AE$41,'[1]감독 순번'!B14)+COUNTIF([1]감독시간표!$E$47:$Q$47,'[1]감독 순번'!B14)+COUNTIF([1]감독시간표!$Y$47:$AC$47,'[1]감독 순번'!B14) -> #VALUE! | F14: =COUNTIF([1]감독시간표!$E$10:$K$11,'[1]감독 순번'!B14)+COUNTIF([1]감독시간표!$E$13:$S$14,'[1]감독 순번'!B14)+COUNTIF([1]감독시간표!$Y$13:$AE$14,'[1]감독 순번'!B14)+COUNTIF([1]감독시간표!$L$16:$S$17,'[1]감독 순번'!B14)+COUNTIF([1]감독시간표!$Y$16:$AE$17,'[1]감독 순번'!B14)+COUNTIF([1]감독시간표!$E$22:$S$23,'[1]감독 순번'!B14)+COUNTIF([1]감독시간표!$Y$22:$AE$23,'[1]감독 순번'!B14)+COUNTIF([1]감독시간표!$L$25:$S$26,'[1]감독 순번'!B14)+COUNTIF([1]감독시간표!$AJ$25:$AK$26,'[1]감독 순번'!B14)+COUNTIF([1]감독시간표!$E$31:$S$32,'[1]감독 순번'!B14)+COUNTIF([1]감독시간표!$Y$31:$AE$32,'[1]감독 순번'!B14)+COUNTIF([1]감독시간표!$W$34:$AE$35,'[1]감독 순번'!B14)+COUNTIF([1]감독시간표!$E$37:$S$38,'[1]감독 순번'!B14)+COUNTIF([1]감독시간표!$Y$37:$AE$38,'[1]감독 순번'!B14)+COUNTIF([1]감독시간표!$E$43:$S$44,'[1]감독 순번'!B14)+COUNTIF([1]감독시간표!$Y$43:$AE$44,'[1]감독 순번'!B14)+COUNTIF([1]감독시간표!$X$46,'[1]감독 순번'!B14)+COUNTIF([1]감독시간표!$AG$46,'[1]감독 순번'!B14) -> #VALUE! | G14: =SUM(D14:F14) -> #VALUE!
B15: 11 | C15: =[1]감독시간표!I52 -> 김윤정 | D15: =COUNTIF([1]감독시간표!$L$10:$S$10,'[1]감독 순번'!B15)+COUNTIF([1]감독시간표!$Y$10:$AE$10,'[1]감독 순번'!B15)+COUNTIF([1]감독시간표!$E$16:$K$16,'[1]감독 순번'!B15)+COUNTIF([1]감독시간표!$T$16:$V$16,'[1]감독 순번'!B15)+COUNTIF([1]감독시간표!$AI$16,'[1]감독 순번'!B15)+COUNTIF([1]감독시간표!$E$19:$S$19,'[1]감독 순번'!B15)+COUNTIF([1]감독시간표!$Y$19:$AE$19,'[1]감독 순번'!B15)+COUNTIF([1]감독시간표!$E$25:$K$25,'[1]감독 순번'!B15)+COUNTIF([1]감독시간표!$T$25:$V$25,'[1]감독 순번'!B15)+COUNTIF([1]감독시간표!$Y$25:$AA$25,'[1]감독 순번'!B15)+COUNTIF([1]감독시간표!$E$28:$S$28,'[1]감독 순번'!B15)+COUNTIF([1]감독시간표!$AA$28:$AC$28,'[1]감독 순번'!B15)+COUNTIF([1]감독시간표!$AF$28:$AI$28,'[1]감독 순번'!B15)+COUNTIF([1]감독시간표!$E$34:$P$34,'[1]감독 순번'!B15)+COUNTIF([1]감독시간표!$AF$34:$AH$34,'[1]감독 순번'!B15)+COUNTIF([1]감독시간표!$E$40:$S$40,'[1]감독 순번'!B15)+COUNTIF([1]감독시간표!$Y$40:$AE$40,'[1]감독 순번'!B15)+COUNTIF([1]감독시간표!$E$46:$Q$46,'[1]감독 순번'!B15)+COUNTIF([1]감독시간표!$Y$46:$AC$46,'[1]감독 순번'!B15) -> #VALUE! | E15: =COUNTIF([1]감독시간표!$L$11:$S$11,'[1]감독 순번'!B15)+COUNTIF([1]감독시간표!$Y$11:$AE$11,'[1]감독 순번'!B15)+COUNTIF([1]감독시간표!$E$17:$K$17,'[1]감독 순번'!B15)+COUNTIF([1]감독시간표!$T$17:$V$17,'[1]감독 순번'!B15)+COUNTIF([1]감독시간표!$AI$17,'[1]감독 순번'!B15)+COUNTIF([1]감독시간표!$E$20:$S$20,'[1]감독 순번'!B15)+COUNTIF([1]감독시간표!$Y$20:$AE$20,'[1]감독 순번'!B15)+COUNTIF([1]감독시간표!$E$26:$K$26,'[1]감독 순번'!B15)+COUNTIF([1]감독시간표!$T$26:$V$26,'[1]감독 순번'!B15)+COUNTIF([1]감독시간표!$Y$26:$AA$26,'[1]감독 순번'!B15)+COUNTIF([1]감독시간표!$E$29:$S$29,'[1]감독 순번'!B15)+COUNTIF([1]감독시간표!$AA$29:$AC$29,'[1]감독 순번'!B15)+COUNTIF([1]감독시간표!$AF$29:$AI$29,'[1]감독 순번'!B15)+COUNTIF([1]감독시간표!$E$35:$P$35,'[1]감독 순번'!B15)+COUNTIF([1]감독시간표!$AF$35:$AH$35,'[1]감독 순번'!B15)+COUNTIF([1]감독시간표!$E$41:$S$41,'[1]감독 순번'!B15)+COUNTIF([1]감독시간표!$Y$41:$AE$41,'[1]감독 순번'!B15)+COUNTIF([1]감독시간표!$E$47:$Q$47,'[1]감독 순번'!B15)+COUNTIF([1]감독시간표!$Y$47:$AC$47,'[1]감독 순번'!B15) -> #VALUE! | F15: =COUNTIF([1]감독시간표!$E$10:$K$11,'[1]감독 순번'!B15)+COUNTIF([1]감독시간표!$E$13:$S$14,'[1]감독 순번'!B15)+COUNTIF([1]감독시간표!$Y$13:$AE$14,'[1]감독 순번'!B15)+COUNTIF([1]감독시간표!$L$16:$S$17,'[1]감독 순번'!B15)+COUNTIF([1]감독시간표!$Y$16:$AE$17,'[1]감독 순번'!B15)+COUNTIF([1]감독시간표!$E$22:$S$23,'[1]감독 순번'!B15)+COUNTIF([1]감독시간표!$Y$22:$AE$23,'[1]감독 순번'!B15)+COUNTIF([1]감독시간표!$L$25:$S$26,'[1]감독 순번'!B15)+COUNTIF([1]감독시간표!$AJ$25:$AK$26,'[1]감독 순번'!B15)+COUNTIF([1]감독시간표!$E$31:$S$32,'[1]감독 순번'!B15)+COUNTIF([1]감독시간표!$Y$31:$AE$32,'[1]감독 순번'!B15)+COUNTIF([1]감독시간표!$W$34:$AE$35,'[1]감독 순번'!B15)+COUNTIF([1]감독시간표!$E$37:$S$38,'[1]감독 순번'!B15)+COUNTIF([1]감독시간표!$Y$37:$AE$38,'[1]감독 순번'!B15)+COUNTIF([1]감독시간표!$E$43:$S$44,'[1]감독 순번'!B15)+COUNTIF([1]감독시간표!$Y$43:$AE$44,'[1]감독 순번'!B15)+COUNTIF([1]감독시간표!$X$46,'[1]감독 순번'!B15)+COUNTIF([1]감독시간표!$AG$46,'[1]감독 순번'!B15) -> #VALUE! | G15: =SUM(D15:F15) -> #VALUE! | P15: 4.29.(월)-4.30.(화) 출장
B16: 12 | C16: =[1]감독시간표!I53 -> 황경화 | D16: =COUNTIF([1]감독시간표!$L$10:$S$10,'[1]감독 순번'!B16)+COUNTIF([1]감독시간표!$Y$10:$AE$10,'[1]감독 순번'!B16)+COUNTIF([1]감독시간표!$E$16:$K$16,'[1]감독 순번'!B16)+COUNTIF([1]감독시간표!$T$16:$V$16,'[1]감독 순번'!B16)+COUNTIF([1]감독시간표!$AI$16,'[1]감독 순번'!B16)+COUNTIF([1]감독시간표!$E$19:$S$19,'[1]감독 순번'!B16)+COUNTIF([1]감독시간표!$Y$19:$AE$19,'[1]감독 순번'!B16)+COUNTIF([1]감독시간표!$E$25:$K$25,'[1]감독 순번'!B16)+COUNTIF([1]감독시간표!$T$25:$V$25,'[1]감독 순번'!B16)+COUNTIF([1]감독시간표!$Y$25:$AA$25,'[1]감독 순번'!B16)+COUNTIF([1]감독시간표!$E$28:$S$28,'[1]감독 순번'!B16)+COUNTIF([1]감독시간표!$AA$28:$AC$28,'[1]감독 순번'!B16)+COUNTIF([1]감독시간표!$AF$28:$AI$28,'[1]감독 순번'!B16)+COUNTIF([1]감독시간표!$E$34:$P$34,'[1]감독 순번'!B16)+COUNTIF([1]감독시간표!$AF$34:$AH$34,'[1]감독 순번'!B16)+COUNTIF([1]감독시간표!$E$40:$S$40,'[1]감독 순번'!B16)+COUNTIF([1]감독시간표!$Y$40:$AE$40,'[1]감독 순번'!B16)+COUNTIF([1]감독시간표!$E$46:$Q$46,'[1]감독 순번'!B16)+COUNTIF([1]감독시간표!$Y$46:$AC$46,'[1]감독 순번'!B16) -> #VALUE! | E16: =COUNTIF([1]감독시간표!$L$11:$S$11,'[1]감독 순번'!B16)+COUNTIF([1]감독시간표!$Y$11:$AE$11,'[1]감독 순번'!B16)+COUNTIF([1]감독시간표!$E$17:$K$17,'[1]감독 순번'!B16)+COUNTIF([1]감독시간표!$T$17:$V$17,'[1]감독 순번'!B16)+COUNTIF([1]감독시간표!$AI$17,'[1]감독 순번'!B16)+COUNTIF([1]감독시간표!$E$20:$S$20,'[1]감독 순번'!B16)+COUNTIF([1]감독시간표!$Y$20:$AE$20,'[1]감독 순번'!B16)+COUNTIF([1]감독시간표!$E$26:$K$26,'[1]감독 순번'!B16)+COUNTIF([1]감독시간표!$T$26:$V$26,'[1]감독 순번'!B16)+COUNTIF([1]감독시간표!$Y$26:$AA$26,'[1]감독 순번'!B16)+COUNTIF([1]감독시간표!$E$29:$S$29,'[1]감독 순번'!B16)+COUNTIF([1]감독시간표!$AA$29:$AC$29,'[1]감독 순번'!B16)+COUNTIF([1]감독시간표!$AF$29:$AI$29,'[1]감독 순번'!B16)+COUNTIF([1]감독시간표!$E$35:$P$35,'[1]감독 순번'!B16)+COUNTIF([1]감독시간표!$AF$35:$AH$35,'[1]감독 순번'!B16)+COUNTIF([1]감독시간표!$E$41:$S$41,'[1]감독 순번'!B16)+COUNTIF([1]감독시간표!$Y$41:$AE$41,'[1]감독 순번'!B16)+COUNTIF([1]감독시간표!$E$47:$Q$47,'[1]감독 순번'!B16)+COUNTIF([1]감독시간표!$Y$47:$AC$47,'[1]감독 순번'!B16) -> #VALUE! | F16: =COUNTIF([1]감독시간표!$E$10:$K$11,'[1]감독 순번'!B16)+COUNTIF([1]감독시간표!$E$13:$S$14,'[1]감독 순번'!B16)+COUNTIF([1]감독시간표!$Y$13:$AE$14,'[1]감독 순번'!B16)+COUNTIF([1]감독시간표!$L$16:$S$17,'[1]감독 순번'!B16)+COUNTIF([1]감독시간표!$Y$16:$AE$17,'[1]감독 순번'!B16)+COUNTIF([1]감독시간표!$E$22:$S$23,'[1]감독 순번'!B16)+COUNTIF([1]감독시간표!$Y$22:$AE$23,'[1]감독 순번'!B16)+COUNTIF([1]감독시간표!$L$25:$S$26,'[1]감독 순번'!B16)+COUNTIF([1]감독시간표!$AJ$25:$AK$26,'[1]감독 순번'!B16)+COUNTIF([1]감독시간표!$E$31:$S$32,'[1]감독 순번'!B16)+COUNTIF([1]감독시간표!$Y$31:$AE$32,'[1]감독 순번'!B16)+COUNTIF([1]감독시간표!$W$34:$AE$35,'[1]감독 순번'!B16)+COUNTIF([1]감독시간표!$E$37:$S$38,'[1]감독 순번'!B16)+COUNTIF([1]감독시간표!$Y$37:$AE$38,'[1]감독 순번'!B16)+COUNTIF([1]감독시간표!$E$43:$S$44,'[1]감독 순번'!B16)+COUNTIF([1]감독시간표!$Y$43:$AE$44,'[1]감독 순번'!B16)+COUNTIF([1]감독시간표!$X$46,'[1]감독 순번'!B16)+COUNTIF([1]감독시간표!$AG$46,'[1]감독 순번'!B16) -> #VALUE! | G16: =SUM(D16:F16) -> #VALUE! | P16: 4.26.(금) 2교시 조퇴
